Workbook
Name 化学均分: '质量分析(总分) '!$D$141:$D$148,'质量分析(总分) '!$D$150:$D$154

Sheet 成绩条打印
A1: 高三上 期末考 | B1: 班级 | C1: 姓名 | D1: 语文 | E1: 数学 | F1: 英语 | G1: 物理 | H1: 化学 | I1: 生物 | J1: 政治 | K1: 历史 | L1: 地理 | M1: 总分
B2: =INDIRECT("'按班级打印'!G"&ROUNDDOWN((ROW()-1)/5,0)+2) -> 1 | C2: =INDIRECT("'按班级打印'!A"&ROUNDDOWN((ROW()-1)/5,0)+2) -> 郑智文 | D2: =INDIRECT("'按班级打印'!M"&ROUNDDOWN((ROW()-1)/5,0)+2) -> 105 | E2: =INDIRECT("'按班级打印'!o"&ROUNDDOWN((ROW()-1)/5,0)+2) -> 70 | F2: =INDIRECT("'按班级打印'!q"&ROUNDDOWN((ROW()-1)/5,0)+2) -> 119 | G2: =IF(INDIRECT("'按班级打印'!s"&ROUNDDOWN((ROW()-1)/5,0)+2)>0,INDIRECT("'按班级打印'!s"&ROUNDDOWN((ROW()-1)/5,0)+2),"") -> 66.5 | H2: =IF(INDIRECT("'按班级打印'!w"&ROUNDDOWN((ROW()-1)/5,0)+2)>0,INDIRECT("'按班级打印'!w"&ROUNDDOWN((ROW()-1)/5,0)+2),"") -> 50.5 | I2: =IF(INDIRECT("'按班级打印'!z"&ROUNDDOWN((ROW()-1)/5,0)+2)>0,INDIRECT("'按班级打印'!z"&ROUNDDOWN((ROW()-1)/5,0)+2),"") -> 64 | J2: =IF(INDIRECT("'按班级打印'!ac"&ROUNDDOWN((ROW()-1)/5,0)+2)>0,INDIRECT("'按班级打印'!ac"&ROUNDDOWN((ROW()-1)/5,0)+2),"") | K2: =IF(INDIRECT("'按班级打印'!u"&ROUNDDOWN((ROW()-1)/5,0)+2)>0,INDIRECT("'按班级打印'!u"&ROUNDDOWN((ROW()-1)/5,0)+2),"") | L2: =IF(INDIRECT("'按班级打印'!af"&ROUNDDOWN((ROW()-1)/5,0)+2)>0,INDIRECT("'按班级打印'!af"&ROUNDDOWN((ROW()-1)/5,0)+2),"") | M2: =INDIRECT("'按班级打印'!H"&ROUNDDOWN((ROW()-1)/5,0)+2) -> 475
C3: 赋分 | D3: =INDIRECT("'按班级打印'!M"&ROUNDDOWN((ROW()-1)/5,0)+2) -> 105 | E3: =INDIRECT("'按班级打印'!o"&ROUNDDOWN((ROW()-1)/5,0)+2) -> 70 | F3: =INDIRECT("'按班级打印'!q"&ROUNDDOWN((ROW()-1)/5,0)+2) -> 119 | G3: =IF(INDIRECT("'按班级打印'!s"&ROUNDDOWN((ROW()-1)/5,0)+2)>0,INDIRECT("'按班级打印'!s"&ROUNDDOWN((ROW()-1)/5,0)+2),"") -> 66.5 | H3: =IF(INDIRECT("'按班级打印'!x"&ROUNDDOWN((ROW()-1)/5,0)+2)>0,INDIRECT("'按班级打印'!x"&ROUNDDOWN((ROW()-1)/5,0)+2),"") -> 76 | I3: =IF(INDIRECT("'按班级打印'!aa"&ROUNDDOWN((ROW()-1)/5,0)+2)>0,INDIRECT("'按班级打印'!aa"&ROUNDDOWN((ROW()-1)/5,0)+2),"") -> 73 | J3: =IF(INDIRECT("'按班级打印'!ad"&ROUNDDOWN((ROW()-1)/5,0)+2)>0,INDIRECT("'按班级打印'!ad"&ROUNDDOWN((ROW()-1)/5,0)+2),"") | K3: =IF(INDIRECT("'按班级打印'!u"&ROUNDDOWN((ROW()-1)/5,0)+2)>0,INDIRECT("'按班级打印'!u"&ROUNDDOWN((ROW()-1)/5,0)+2),"") | L3: =IF(INDIRECT("'按班级打印'!ag"&ROUNDDOWN((ROW()-1)/5,0)+2)>0,INDIRECT("'按班级打印'!ag"&ROUNDDOWN((ROW()-1)/5,0)+2),"") | M3: =INDIRECT("'按班级打印'!I"&ROUNDDOWN((ROW()-1)/5,0)+2) -> 509.5
A4: =INDIRECT("'按班级打印'!E"&ROUNDDOWN((ROW()-1)/5,0)+2) -> 物理类 | C4: 平均分 | D4: ='质量分析(总分) '!$D$55 -> 105.00061 | E4: ='质量分析(总分) '!$D$82 -> 91.524203 | F4: ='质量分析(总分) '!$D$109 -> 108.86397 | G4: =IF(_xlfn.NUMBERVALUE(G2)>0,'质量分析(总分) '!$D$133,"") -> 62.652143 | H4: =IF(_xlfn.NUMBERVALUE(H2)>0,'质量分析(总分) '!$D$157,"") -> 81.868613 | I4: =IF(_xlfn.NUMBERVALUE(I2)>0,'质量分析(总分) '!$D$180,"") -> 83.367647 | J4: =IF(_xlfn.NUMBERVALUE(J2)>0,'质量分析(总分) '!$D$208,"") | K4: =IF(_xlfn.NUMBERVALUE(K2)>0,'质量分析(总分) '!$D$194,"") | L4: =IF(_xlfn.NUMBERVALUE(L2)>0,'质量分析(总分) '!$D$222,"") | M4: =IF(_xlfn.NUMBERVALUE(G2)>0,'质量分析(总分) '!$D$23,'质量分析(总分) '!$D$28) -> 535.86929
A6: 高三上 期末考 | B6: 班级 | C6: 姓名 | D6: 语文 | E6: 数学 | F6: 英语 | G6: 物理 | H6: 化学 | I6: 生物 | J6: 政治 | K6: 历史 | L6: 地理 | M6: 总分
B7: =INDIRECT("'按班级打印'!G"&ROUNDDOWN((ROW()-1)/5,0)+2) -> 1 | C7: =INDIRECT("'按班级打印'!A"&ROUNDDOWN((ROW()-1)/5,0)+2) -> 林慧 | D7: =INDIRECT("'按班级打印'!M"&ROUNDDOWN((ROW()-1)/5,0)+2) -> 89 | E7: =INDIRECT("'按班级打印'!o"&ROUNDDOWN((ROW()-1)/5,0)+2) -> 114 | F7: =INDIRECT("'按班级打印'!q"&ROUNDDOWN((ROW()-1)/5,0)+2) -> 87 | G7: =IF(INDIRECT("'按班级打印'!s"&ROUNDDOWN((ROW()-1)/5,0)+2)>0,INDIRECT("'按班级打印'!s"&ROUNDDOWN((ROW()-1)/5,0)+2),"") -> 60 | H7: =IF(INDIRECT("'按班级打印'!w"&ROUNDDOWN((ROW()-1)/5,0)+2)>0,INDIRECT("'按班级打印'!w"&ROUNDDOWN((ROW()-1)/5,0)+2),"") -> 62 | I7: =IF(INDIRECT("'按班级打印'!z"&ROUNDDOWN((ROW()-1)/5,0)+2)>0,INDIRECT("'按班级打印'!z"&ROUNDDOWN((ROW()-1)/5,0)+2),"") -> 73.5 | J7: =IF(INDIRECT("'按班级打印'!ac"&ROUNDDOWN((ROW()-1)/5,0)+2)>0,INDIRECT("'按班级打印'!ac"&ROUNDDOWN((ROW()-1)/5,0)+2),"") | K7: =IF(INDIRECT("'按班级打印'!u"&ROUNDDOWN((ROW()-1)/5,0)+2)>0,INDIRECT("'按班级打印'!u"&ROUNDDOWN((ROW()-1)/5,0)+2),"") | L7: =IF(INDIRECT("'按班级打印'!af"&ROUNDDOWN((ROW()-1)/5,0)+2)>0,INDIRECT("'按班级打印'!af"&ROUNDDOWN((ROW()-1)/5,0)+2),"") | M7: =INDIRECT("'按班级打印'!H"&ROUNDDOWN((ROW()-1)/5,0)+2) -> 485.5
C8: 赋分 | D8: =INDIRECT("'按班级打印'!M"&ROUNDDOWN((ROW()-1)/5,0)+2) -> 89 | E8: =INDIRECT("'按班级打印'!o"&ROUNDDOWN((ROW()-1)/5,0)+2) -> 114 | F8: =INDIRECT("'按班级打印'!q"&ROUNDDOWN((ROW()-1)/5,0)+2) -> 87 | G8: =IF(INDIRECT("'按班级打印'!s"&ROUNDDOWN((ROW()-1)/5,0)+2)>0,INDIRECT("'按班级打印'!s"&ROUNDDOWN((ROW()-1)/5,0)+2),"") -> 60 | H8: =IF(INDIRECT("'按班级打印'!x"&ROUNDDOWN((ROW()-1)/5,0)+2)>0,INDIRECT("'按班级打印'!x"&ROUNDDOWN((ROW()-1)/5,0)+2),"") -> 85 | I8: =IF(INDIRECT("'按班级打印'!aa"&ROUNDDOWN((ROW()-1)/5,0)+2)>0,INDIRECT("'按班级打印'!aa"&ROUNDDOWN((ROW()-1)/5,0)+2),"") -> 82 | J8: =IF(INDIRECT("'按班级打印'!ad"&ROUNDDOWN((ROW()-1)/5,0)+2)>0,INDIRECT("'按班级打印'!ad"&ROUNDDOWN((ROW()-1)/5,0)+2),"") | K8: =IF(INDIRECT("'按班级打印'!u"&ROUNDDOWN((ROW()-1)/5,0)+2)>0,INDIRECT("'按班级打印'!u"&ROUNDDOWN((ROW()-1)/5,0)+2),"") | L8: =IF(INDIRECT("'按班级打印'!ag"&ROUNDDOWN((ROW()-1)/5,0)+2)>0,INDIRECT("'按班级打印'!ag"&ROUNDDOWN((ROW()-1)/5,0)+2),"") | M8: =INDIRECT("'按班级打印'!I"&ROUNDDOWN((ROW()-1)/5,0)+2) -> 517
A9: =INDIRECT("'按班级打印'!E"&ROUNDDOWN((ROW()-1)/5,0)+2) -> 物理类 | C9: 平均分 | D9: ='质量分析(总分) '!$D$55 -> 105.00061 | E9: ='质量分析(总分) '!$D$82 -> 91.524203 | F9: ='质量分析(总分) '!$D$109 -> 108.86397 | G9: =IF(_xlfn.NUMBERVALUE(G7)>0,'质量分析(总分) '!$D$133,"") -> 62.652143 | H9: =IF(_xlfn.NUMBERVALUE(H7)>0,'质量分析(总分) '!$D$157,"") -> 81.868613 | I9: =IF(_xlfn.NUMBERVALUE(I7)>0,'质量分析(总分) '!$D$180,"") -> 83.367647 | J9: =IF(_xlfn.NUMBERVALUE(J7)>0,'质量分析(总分) '!$D$208,"") | K9: =IF(_xlfn.NUMBERVALUE(K7)>0,'质量分析(总分) '!$D$194,"") | L9: =IF(_xlfn.NUMBERVALUE(L7)>0,'质量分析(总分) '!$D$222,"") | M9: =IF(_xlfn.NUMBERVALUE(G7)>0,'质量分析(总分) '!$D$23,'质量分析(总分) '!$D$28) -> 535.86929
A11: 高三上 期末考 | B11: 班级 | C11: 姓名 | D11: 语文 | E11: 数学 | F11: 英语 | G11: 物理 | H11: 化学 | I11: 生物 | J11: 政治 | K11: 历史 | L11: 地理 | M11: 总分
B12: =INDIRECT("'按班级打印'!G"&ROUNDDOWN((ROW()-1)/5,0)+2) -> 1 | C12: =INDIRECT("'按班级打印'!A"&ROUNDDOWN((ROW()-1)/5,0)+2) -> 钟林斌 | D12: =INDIRECT("'按班级打印'!M"&ROUNDDOWN((ROW()-1)/5,0)+2) -> 100.5 | E12: =INDIRECT("'按班级打印'!o"&ROUNDDOWN((ROW()-1)/5,0)+2) -> 108.5 | F12: =INDIRECT("'按班级打印'!q"&ROUNDDOWN((ROW()-1)/5,0)+2) -> 116.5 | G12: =IF(INDIRECT("'按班级打印'!s"&ROUNDDOWN((ROW()-1)/5,0)+2)>0,INDIRECT("'按班级打印'!s"&ROUNDDOWN((ROW()-1)/5,0)+2),"") -> 61.5 | H12: =IF(INDIRECT("'按班级打印'!w"&ROUNDDOWN((ROW()-1)/5,0)+2)>0,INDIRECT("'按班级打印'!w"&ROUNDDOWN((ROW()-1)/5,0)+2),"") -> 65.5 | I12: =IF(INDIRECT("'按班级打印'!z"&ROUNDDOWN((ROW()-1)/5,0)+2)>0,INDIRECT("'按班级打印'!z"&ROUNDDOWN((ROW()-1)/5,0)+2),"") -> 84.5 | J12: =IF(INDIRECT("'按班级打印'!ac"&ROUNDDOWN((ROW()-1)/5,0)+2)>0,INDIRECT("'按班级打印'!ac"&ROUNDDOWN((ROW()-1)/5,0)+2),"") | K12: =IF(INDIRECT("'按班级打印'!u"&ROUNDDOWN((ROW()-1)/5,0)+2)>0,INDIRECT("'按班级打印'!u"&ROUNDDOWN((ROW()-1)/5,0)+2),"") | L12: =IF(INDIRECT("'按班级打印'!af"&ROUNDDOWN((ROW()-1)/5,0)+2)>0,INDIRECT("'按班级打印'!af"&ROUNDDOWN((ROW()-1)/5,0)+2),"") | M12: =INDIRECT("'按班级打印'!H"&ROUNDDOWN((ROW()-1)/5,0)+2) -> 537
C13: 赋分 | D13: =INDIRECT("'按班级打印'!M"&ROUNDDOWN((ROW()-1)/5,0)+2) -> 100.5 | E13: =INDIRECT("'按班级打印'!o"&ROUNDDOWN((ROW()-1)/5,0)+2) -> 108.5 | F13: =INDIRECT("'按班级打印'!q"&ROUNDDOWN((ROW()-1)/5,0)+2) -> 116.5 | G13: =IF(INDIRECT("'按班级打印'!s"&ROUNDDOWN((ROW()-1)/5,0)+2)>0,INDIRECT("'按班级打印'!s"&ROUNDDOWN((ROW()-1)/5,0)+2),"") -> 61.5 | H13: =IF(INDIRECT("'按班级打印'!x"&ROUNDDOWN((ROW()-1)/5,0)+2)>0,INDIRECT("'按班级打印'!x"&ROUNDDOWN((ROW()-1)/5,0)+2),"") -> 87 | I13: =IF(INDIRECT("'按班级打印'!aa"&ROUNDDOWN((ROW()-1)/5,0)+2)>0,INDIRECT("'按班级打印'!aa"&ROUNDDOWN((ROW()-1)/5,0)+2),"") -> 92 | J13: =IF(INDIRECT("'按班级打印'!ad"&ROUNDDOWN((ROW()-1)/5,0)+2)>0,INDIRECT("'按班级打印'!ad"&ROUNDDOWN((ROW()-1)/5,0)+2),"") | K13: =IF(INDIRECT("'按班级打印'!u"&ROUNDDOWN((ROW()-1)/5,0)+2)>0,INDIRECT("'按班级打印'!u"&ROUNDDOWN((ROW()-1)/5,0)+2),"") | L13: =IF(INDIRECT("'按班级打印'!ag"&ROUNDDOWN((ROW()-1)/5,0)+2)>0,INDIRECT("'按班级打印'!ag"&ROUNDDOWN((ROW()-1)/5,0)+2),"") | M13: =INDIRECT("'按班级打印'!I"&ROUNDDOWN((ROW()-1)/5,0)+2) -> 566
A14: =INDIRECT("'按班级打印'!E"&ROUNDDOWN((ROW()-1)/5,0)+2) -> 物理类 | C14: 平均分 | D14: ='质量分析(总分) '!$D$55 -> 105.00061 | E14: ='质量分析(总分) '!$D$82 -> 91.524203 | F14: ='质量分析(总分) '!$D$109 -> 108.86397 | G14: =IF(_xlfn.NUMBERVALUE(G12)>0,'质量分析(总分) '!$D$133,"") -> 62.652143 | H14: =IF(_xlfn.NUMBERVALUE(H12)>0,'质量分析(总分) '!$D$157,"") -> 81.868613 | I14: =IF(_xlfn.NUMBERVALUE(I12)>0,'质量分析(总分) '!$D$180,"") -> 83.367647 | J14: =IF(_xlfn.NUMBERVALUE(J12)>0,'质量分析(总分) '!$D$208,"") | K14: =IF(_xlfn.NUMBERVALUE(K12)>0,'质量分析(总分) '!$D$194,"") | L14: =IF(_xlfn.NUMBERVALUE(L12)>0,'质量分析(总分) '!$D$222,"") | M14: =IF(_xlfn.NUMBERVALUE(G12)>0,'质量分析(总分) '!$D$23,'质量分析(总分) '!$D$28) -> 535.86929
A16: 高三上 期末考 | B16: 班级 | C16: 姓名 | D16: 语文 | E16: 数学 | F16: 英语 | G16: 物理 | H16: 化学 | I16: 生物 | J16: 政治 | K16: 历史 | L16: 地理 | M16: 总分
B17: =INDIRECT("'按班级打印'!G"&ROUNDDOWN((ROW()-1)/5,0)+2) -> 1 | C17: =INDIRECT("'按班级打印'!A"&ROUNDDOWN((ROW()-1)/5,0)+2) -> 占谨豪 | D17: =INDIRECT("'按班级打印'!M"&ROUNDDOWN((ROW()-1)/5,0)+2) -> 105 | E17: =INDIRECT("'按班级打印'!o"&ROUNDDOWN((ROW()-1)/5,0)+2) -> 78.5 | F17: =INDIRECT("'按班级打印'!q"&ROUNDDOWN((ROW()-1)/5,0)+2) -> 85.5 | G17: =IF(INDIRECT("'按班级打印'!s"&ROUNDDOWN((ROW()-1)/5,0)+2)>0,INDIRECT("'按班级打印'!s"&ROUNDDOWN((ROW()-1)/5,0)+2),"") -> 62 | H17: =IF(INDIRECT("'按班级打印'!w"&ROUNDDOWN((ROW()-1)/5,0)+2)>0,INDIRECT("'按班级打印'!w"&ROUNDDOWN((ROW()-1)/5,0)+2),"") -> 50 | I17: =IF(INDIRECT("'按班级打印'!z"&ROUNDDOWN((ROW()-1)/5,0)+2)>0,INDIRECT("'按班级打印'!z"&ROUNDDOWN((ROW()-1)/5,0)+2),"") -> 69 | J17: =IF(INDIRECT("'按班级打印'!ac"&ROUNDDOWN((ROW()-1)/5,0)+2)>0,INDIRECT("'按班级打印'!ac"&ROUNDDOWN((ROW()-1)/5,0)+2),"") | K17: =IF(INDIRECT("'按班级打印'!u"&ROUNDDOWN((ROW()-1)/5,0)+2)>0,INDIRECT("'按班级打印'!u"&ROUNDDOWN((ROW()-1)/5,0)+2),"") | L17: =IF(INDIRECT("'按班级打印'!af"&ROUNDDOWN((ROW()-1)/5,0)+2)>0,INDIRECT("'按班级打印'!af"&ROUNDDOWN((ROW()-1)/5,0)+2),"") | M17: =INDIRECT("'按班级打印'!H"&ROUNDDOWN((ROW()-1)/5,0)+2) -> 450
C18: 赋分 | D18: =INDIRECT("'按班级打印'!M"&ROUNDDOWN((ROW()-1)/5,0)+2) -> 105 | E18: =INDIRECT("'按班级打印'!o"&ROUNDDOWN((ROW()-1)/5,0)+2) -> 78.5 | F18: =INDIRECT("'按班级打印'!q"&ROUNDDOWN((ROW()-1)/5,0)+2) -> 85.5 | G18: =IF(INDIRECT("'按班级打印'!s"&ROUNDDOWN((ROW()-1)/5,0)+2)>0,INDIRECT("'按班级打印'!s"&ROUNDDOWN((ROW()-1)/5,0)+2),"") -> 62 | H18: =IF(INDIRECT("'按班级打印'!x"&ROUNDDOWN((ROW()-1)/5,0)+2)>0,INDIRECT("'按班级打印'!x"&ROUNDDOWN((ROW()-1)/5,0)+2),"") -> 76 | I18: =IF(INDIRECT("'按班级打印'!aa"&ROUNDDOWN((ROW()-1)/5,0)+2)>0,INDIRECT("'按班级打印'!aa"&ROUNDDOWN((ROW()-1)/5,0)+2),"") -> 78 | J18: =IF(INDIRECT("'按班级打印'!ad"&ROUNDDOWN((ROW()-1)/5,0)+2)>0,INDIRECT("'按班级打印'!ad"&ROUNDDOWN((ROW()-1)/5,0)+2),"") | K18: =IF(INDIRECT("'按班级打印'!u"&ROUNDDOWN((ROW()-1)/5,0)+2)>0,INDIRECT("'按班级打印'!u"&ROUNDDOWN((ROW()-1)/5,0)+2),"") | L18: =IF(INDIRECT("'按班级打印'!ag"&ROUNDDOWN((ROW()-1)/5,0)+2)>0,INDIRECT("'按班级打印'!ag"&ROUNDDOWN((ROW()-1)/5,0)+2),"") | M18: =INDIRECT("'按班级打印'!I"&ROUNDDOWN((ROW()-1)/5,0)+2) -> 485
A19: =INDIRECT("'按班级打印'!E"&ROUNDDOWN((ROW()-1)/5,0)+2) -> 物理类 | C19: 平均分 | D19: ='质量分析(总分) '!$D$55 -> 105.00061 | E19: ='质量分析(总分) '!$D$82 -> 91.524203 | F19: ='质量分析(总分) '!$D$109 -> 108.86397 | G19: =IF(_xlfn.NUMBERVALUE(G17)>0,'质量分析(总分) '!$D$133,"") -> 62.652143 | H19: =IF(_xlfn.NUMBERVALUE(H17)>0,'质量分析(总分) '!$D$157,"") -> 81.868613 | I19: =IF(_xlfn.NUMBERVALUE(I17)>0,'质量分析(总分) '!$D$180,"") -> 83.367647 | J19: =IF(_xlfn.NUMBERVALUE(J17)>0,'质量分析(总分) '!$D$208,"") | K19: =IF(_xlfn.NUMBERVALUE(K17)>0,'质量分析(总分) '!$D$194,"") | L19: =IF(_xlfn.NUMBERVALUE(L17)>0,'质量分析(总分) '!$D$222,"") | M19: =IF(_xlfn.NUMBERVALUE(G17)>0,'质量分析(总分) '!$D$23,'质量分析(总分) '!$D$28) -> 535.86929
A21: 高三上 期末考 | B21: 班级 | C21: 姓名 | D21: 语文 | E21: 数学 | F21: 英语 | G21: 物理 | H21: 化学 | I21: 生物 | J21: 政治 | K21: 历史 | L21: 地理 | M21: 总分
B22: =INDIRECT("'按班级打印'!G"&ROUNDDOWN((ROW()-1)/5,0)+2) -> 1 | C22: =INDIRECT("'按班级打印'!A"&ROUNDDOWN((ROW()-1)/5,0)+2) -> 雷雯颖 | D22: =INDIRECT("'按班级打印'!M"&ROUNDDOWN((ROW()-1)/5,0)+2) -> 102 | E22: =INDIRECT("'按班级打印'!o"&ROUNDDOWN((ROW()-1)/5,0)+2) -> 79.5 | F22: =INDIRECT("'按班级打印'!q"&ROUNDDOWN((ROW()-1)/5,0)+2) -> 111.5 | G22: =IF(INDIRECT("'按班级打印'!s"&ROUNDDOWN((ROW()-1)/5,0)+2)>0,INDIRECT("'按班级打印'!s"&ROUNDDOWN((ROW()-1)/5,0)+2),"") -> 67.5 | H22: =IF(INDIRECT("'按班级打印'!w"&ROUNDDOWN((ROW()-1)/5,0)+2)>0,INDIRECT("'按班级打印'!w"&ROUNDDOWN((ROW()-1)/5,0)+2),"") -> 56 | I22: =IF(INDIRECT("'按班级打印'!z"&ROUNDDOWN((ROW()-1)/5,0)+2)>0,INDIRECT("'按班级打印'!z"&ROUNDDOWN((ROW()-1)/5,0)+2),"") -> 78.5 | J22: =IF(INDIRECT("'按班级打印'!ac"&ROUNDDOWN((ROW()-1)/5,0)+2)>0,INDIRECT("'按班级打印'!ac"&ROUNDDOWN((ROW()-1)/5,0)+2),"") | K22: =IF(INDIRECT("'按班级打印'!u"&ROUNDDOWN((ROW()-1)/5,0)+2)>0,INDIRECT("'按班级打印'!u"&ROUNDDOWN((ROW()-1)/5,0)+2),"") | L22: =IF(INDIRECT("'按班级打印'!af"&ROUNDDOWN((ROW()-1)/5,0)+2)>0,INDIRECT("'按班级打印'!af"&ROUNDDOWN((ROW()-1)/5,0)+2),"") | M22: =INDIRECT("'按班级打印'!H"&ROUNDDOWN((ROW()-1)/5,0)+2) -> 495
C23: 赋分 | D23: =INDIRECT("'按班级打印'!M"&ROUNDDOWN((ROW()-1)/5,0)+2) -> 102 | E23: =INDIRECT("'按班级打印'!o"&ROUNDDOWN((ROW()-1)/5,0)+2) -> 79.5 | F23: =INDIRECT("'按班级打印'!q"&ROUNDDOWN((ROW()-1)/5,0)+2) -> 111.5 | G23: =IF(INDIRECT("'按班级打印'!s"&ROUNDDOWN((ROW()-1)/5,0)+2)>0,INDIRECT("'按班级打印'!s"&ROUNDDOWN((ROW()-1)/5,0)+2),"") -> 67.5 | H23: =IF(INDIRECT("'按班级打印'!x"&ROUNDDOWN((ROW()-1)/5,0)+2)>0,INDIRECT("'按班级打印'!x"&ROUNDDOWN((ROW()-1)/5,0)+2),"") -> 80 | I23: =IF(INDIRECT("'按班级打印'!aa"&ROUNDDOWN((ROW()-1)/5,0)+2)>0,INDIRECT("'按班级打印'!aa"&ROUNDDOWN((ROW()-1)/5,0)+2),"") -> 87 | J23: =IF(INDIRECT("'按班级打印'!ad"&ROUNDDOWN((ROW()-1)/5,0)+2)>0,INDIRECT("'按班级打印'!ad"&ROUNDDOWN((ROW()-1)/5,0)+2),"") | K23: =IF(INDIRECT("'按班级打印'!u"&ROUNDDOWN((ROW()-1)/5,0)+2)>0,INDIRECT("'按班级打印'!u"&ROUNDDOWN((ROW()-1)/5,0)+2),"") | L23: =IF(INDIRECT("'按班级打印'!ag"&ROUNDDOWN((ROW()-1)/5,0)+2)>0,INDIRECT("'按班级打印'!ag"&ROUNDDOWN((ROW()-1)/5,0)+2),"") | M23: =INDIRECT("'按班级打印'!I"&ROUNDDOWN((ROW()-1)/5,0)+2) -> 527.5
A24: =INDIRECT("'按班级打印'!E"&ROUNDDOWN((ROW()-1)/5,0)+2) -> 物理类 | C24: 平均分 | D24: ='质量分析(总分) '!$D$55 -> 105.00061 | E24: ='质量分析(总分) '!$D$82 -> 91.524203 | F24: ='质量分析(总分) '!$D$109 -> 108.86397 | G24: =IF(_xlfn.NUMBERVALUE(G22)>0,'质量分析(总分) '!$D$133,"") -> 62.652143 | H24: =IF(_xlfn.NUMBERVALUE(H22)>0,'质量分析(总分) '!$D$157,"") -> 81.868613 | I24: =IF(_xlfn.NUMBERVALUE(I22)>0,'质量分析(总分) '!$D$180,"") -> 83.367647 | J24: =IF(_xlfn.NUMBERVALUE(J22)>0,'质量分析(总分) '!$D$208,"") | K24: =IF(_xlfn.NUMBERVALUE(K22)>0,'质量分析(总分) '!$D$194,"") | L24: =IF(_xlfn.NUMBERVALUE(L22)>0,'质量分析(总分) '!$D$222,"") | M24: =IF(_xlfn.NUMBERVALUE(G22)>0,'质量分析(总分) '!$D$23,'质量分析(总分) '!$D$28) -> 535.86929
A26: 高三上 期末考 | B26: 班级 | C26: 姓名 | D26: 语文 | E26: 数学 | F26: 英语 | G26: 物理 | H26: 化学 | I26: 生物 | J26: 政治 | K26: 历史 | L26: 地理 | M26: 总分
B27: =INDIRECT("'按班级打印'!G"&ROUNDDOWN((ROW()-1)/5,0)+2) -> 1 | C27: =INDIRECT("'按班级打印'!A"&ROUNDDOWN((ROW()-1)/5,0)+2) -> 陈静怡 | D27: =INDIRECT("'按班级打印'!M"&ROUNDDOWN((ROW()-1)/5,0)+2) -> 101.5 | E27: =INDIRECT("'按班级打印'!o"&ROUNDDOWN((ROW()-1)/5,0)+2) -> 96.5 | F27: =INDIRECT("'按班级打印'!q"&ROUNDDOWN((ROW()-1)/5,0)+2) -> 113 | G27: =IF(INDIRECT("'按班级打印'!s"&ROUNDDOWN((ROW()-1)/5,0)+2)>0,INDIRECT("'按班级打印'!s"&ROUNDDOWN((ROW()-1)/5,0)+2),"") -> 77 | H27: =IF(INDIRECT("'按班级打印'!w"&ROUNDDOWN((ROW()-1)/5,0)+2)>0,INDIRECT("'按班级打印'!w"&ROUNDDOWN((ROW()-1)/5,0)+2),"") -> 65 | I27: =IF(INDIRECT("'按班级打印'!z"&ROUNDDOWN((ROW()-1)/5,0)+2)>0,INDIRECT("'按班级打印'!z"&ROUNDDOWN((ROW()-1)/5,0)+2),"") -> 78 | J27: =IF(INDIRECT("'按班级打印'!ac"&ROUNDDOWN((ROW()-1)/5,0)+2)>0,INDIRECT("'按班级打印'!ac"&ROUNDDOWN((ROW()-1)/5,0)+2),"") | K27: =IF(INDIRECT("'按班级打印'!u"&ROUNDDOWN((ROW()-1)/5,0)+2)>0,INDIRECT("'按班级打印'!u"&ROUNDDOWN((ROW()-1)/5,0)+2),"") | L27: =IF(INDIRECT("'按班级打印'!af"&ROUNDDOWN((ROW()-1)/5,0)+2)>0,INDIRECT("'按班级打印'!af"&ROUNDDOWN((ROW()-1)/5,0)+2),"") | M27: =INDIRECT("'按班级打印'!H"&ROUNDDOWN((ROW()-1)/5,0)+2) -> 531
C28: 赋分 | D28: =INDIRECT("'按班级打印'!M"&ROUNDDOWN((ROW()-1)/5,0)+2) -> 101.5 | E28: =INDIRECT("'按班级打印'!o"&ROUNDDOWN((ROW()-1)/5,0)+2) -> 96.5 | F28: =INDIRECT("'按班级打印'!q"&ROUNDDOWN((ROW()-1)/5,0)+2) -> 113 | G28: =IF(INDIRECT("'按班级打印'!s"&ROUNDDOWN((ROW()-1)/5,0)+2)>0,INDIRECT("'按班级打印'!s"&ROUNDDOWN((ROW()-1)/5,0)+2),"") -> 77 | H28: =IF(INDIRECT("'按班级打印'!x"&ROUNDDOWN((ROW()-1)/5,0)+2)>0,INDIRECT("'按班级打印'!x"&ROUNDDOWN((ROW()-1)/5,0)+2),"") -> 87 | I28: =IF(INDIRECT("'按班级打印'!aa"&ROUNDDOWN((ROW()-1)/5,0)+2)>0,INDIRECT("'按班级打印'!aa"&ROUNDDOWN((ROW()-1)/5,0)+2),"") -> 87 | J28: =IF(INDIRECT("'按班级打印'!ad"&ROUNDDOWN((ROW()-1)/5,0)+2)>0,INDIRECT("'按班级打印'!ad"&ROUNDDOWN((ROW()-1)/5,0)+2),"") | K28: =IF(INDIRECT("'按班级打印'!u"&ROUNDDOWN((ROW()-1)/5,0)+2)>0,INDIRECT("'按班级打印'!u"&ROUNDDOWN((ROW()-1)/5,0)+2),"") | L28: =IF(INDIRECT("'按班级打印'!ag"&ROUNDDOWN((ROW()-1)/5,0)+2)>0,INDIRECT("'按班级打印'!ag"&ROUNDDOWN((ROW()-1)/5,0)+2),"") | M28: =INDIRECT("'按班级打印'!I"&ROUNDDOWN((ROW()-1)/5,0)+2) -> 562
A29: =INDIRECT("'按班级打印'!E"&ROUNDDOWN((ROW()-1)/5,0)+2) -> 物理类 | C29: 平均分 | D29: ='质量分析(总分) '!$D$55 -> 105.00061 | E29: ='质量分析(总分) '!$D$82 -> 91.524203 | F29: ='质量分析(总分) '!$D$109 -> 108.86397 | G29: =IF(_xlfn.NUMBERVALUE(G27)>0,'质量分析(总分) '!$D$133,"") -> 62.652143 | H29: =IF(_xlfn.NUMBERVALUE(H27)>0,'质量分析(总分) '!$D$157,"") -> 81.868613 | I29: =IF(_xlfn.NUMBERVALUE(I27)>0,'质量分析(总分) '!$D$180,"") -> 83.367647 | J29: =IF(_xlfn.NUMBERVALUE(J27)>0,'质量分析(总分) '!$D$208,"") | K29: =IF(_xlfn.NUMBERVALUE(K27)>0,'质量分析(总分) '!$D$194,"") | L29: =IF(_xlfn.NUMBERVALUE(L27)>0,'质量分析(总分) '!$D$222,"") | M29: =IF(_xlfn.NUMBERVALUE(G27)>0,'质量分析(总分) '!$D$23,'质量分析(总分) '!$D$28) -> 535.86929
A31: 高三上 期末考 | B31: 班级 | C31: 姓名 | D31: 语文 | E31: 数学 | F31: 英语 | G31: 物理 | H31: 化学 | I31: 生物 | J31: 政治 | K31: 历史 | L31: 地理 | M31: 总分
B32: =INDIRECT("'按班级打印'!G"&ROUNDDOWN((ROW()-1)/5,0)+2) -> 1 | C32: =INDIRECT("'按班级打印'!A"&ROUNDDOWN((ROW()-1)/5,0)+2) -> 吴冠轩 | D32: =INDIRECT("'按班级打印'!M"&ROUNDDOWN((ROW()-1)/5,0)+2) -> 106 | E32: =INDIRECT("'按班级打印'!o"&ROUNDDOWN((ROW()-1)/5,0)+2) -> 107 | F32: =INDIRECT("'按班级打印'!q"&ROUNDDOWN((ROW()-1)/5,0)+2) -> 107.5 | G32: =IF(INDIRECT("'按班级打印'!s"&ROUNDDOWN((ROW()-1)/5,0)+2)>0,INDIRECT("'按班级打印'!s"&ROUNDDOWN((ROW()-1)/5,0)+2),"") -> 78 | H32: =IF(INDIRECT("'按班级打印'!w"&ROUNDDOWN((ROW()-1)/5,0)+2)>0,INDIRECT("'按班级打印'!w"&ROUNDDOWN((ROW()-1)/5,0)+2),"") -> 69.5 | I32: =IF(INDIRECT("'按班级打印'!z"&ROUNDDOWN((ROW()-1)/5,0)+2)>0,INDIRECT("'按班级打印'!z"&ROUNDDOWN((ROW()-1)/5,0)+2),"") -> 78.5 | J32: =IF(INDIRECT("'按班级打印'!ac"&ROUNDDOWN((ROW()-1)/5,0)+2)>0,INDIRECT("'按班级打印'!ac"&ROUNDDOWN((ROW()-1)/5,0)+2),"") | K32: =IF(INDIRECT("'按班级打印'!u"&ROUNDDOWN((ROW()-1)/5,0)+2)>0,INDIRECT("'按班级打印'!u"&ROUNDDOWN((ROW()-1)/5,0)+2),"") | L32: =IF(INDIRECT("'按班级打印'!af"&ROUNDDOWN((ROW()-1)/5,0)+2)>0,INDIRECT("'按班级打印'!af"&ROUNDDOWN((ROW()-1)/5,0)+2),"") | M32: =INDIRECT("'按班级打印'!H"&ROUNDDOWN((ROW()-1)/5,0)+2) -> 546.5
C33: 赋分 | D33: =INDIRECT("'按班级打印'!M"&ROUNDDOWN((ROW()-1)/5,0)+2) -> 106 | E33: =INDIRECT("'按班级打印'!o"&ROUNDDOWN((ROW()-1)/5,0)+2) -> 107 | F33: =INDIRECT("'按班级打印'!q"&ROUNDDOWN((ROW()-1)/5,0)+2) -> 107.5 | G33: =IF(INDIRECT("'按班级打印'!s"&ROUNDDOWN((ROW()-1)/5,0)+2)>0,INDIRECT("'按班级打印'!s"&ROUNDDOWN((ROW()-1)/5,0)+2),"") -> 78 | H33: =IF(INDIRECT("'按班级打印'!x"&ROUNDDOWN((ROW()-1)/5,0)+2)>0,INDIRECT("'按班级打印'!x"&ROUNDDOWN((ROW()-1)/5,0)+2),"") -> 89 | I33: =IF(INDIRECT("'按班级打印'!aa"&ROUNDDOWN((ROW()-1)/5,0)+2)>0,INDIRECT("'按班级打印'!aa"&ROUNDDOWN((ROW()-1)/5,0)+2),"") -> 87 | J33: =IF(INDIRECT("'按班级打印'!ad"&ROUNDDOWN((ROW()-1)/5,0)+2)>0,INDIRECT("'按班级打印'!ad"&ROUNDDOWN((ROW()-1)/5,0)+2),"") | K33: =IF(INDIRECT("'按班级打印'!u"&ROUNDDOWN((ROW()-1)/5,0)+2)>0,INDIRECT("'按班级打印'!u"&ROUNDDOWN((ROW()-1)/5,0)+2),"") | L33: =IF(INDIRECT("'按班级打印'!ag"&ROUNDDOWN((ROW()-1)/5,0)+2)>0,INDIRECT("'按班级打印'!ag"&ROUNDDOWN((ROW()-1)/5,0)+2),"") | M33: =INDIRECT("'按班级打印'!I"&ROUNDDOWN((ROW()-1)/5,0)+2) -> 574.5
A34: =INDIRECT("'按班级打印'!E"&ROUNDDOWN((ROW()-1)/5,0)+2) -> 物理类 | C34: 平均分 | D34: ='质量分析(总分) '!$D$55 -> 105.00061 | E34: ='质量分析(总分) '!$D$82 -> 91.524203 | F34: ='质量分析(总分) '!$D$109 -> 108.86397 | G34: =IF(_xlfn.NUMBERVALUE(G32)>0,'质量分析(总分) '!$D$133,"") -> 62.652143 | H34: =IF(_xlfn.NUMBERVALUE(H32)>0,'质量分析(总分) '!$D$157,"") -> 81.868613 | I34: =IF(_xlfn.NUMBERVALUE(I32)>0,'质量分析(总分) '!$D$180,"") -> 83.367647 | J34: =IF(_xlfn.NUMBERVALUE(J32)>0,'质量分析(总分) '!$D$208,"") | K34: =IF(_xlfn.NUMBERVALUE(K32)>0,'质量分析(总分) '!$D$194,"") | L34: =IF(_xlfn.NUMBERVALUE(L32)>0,'质量分析(总分) '!$D$222,"") | M34: =IF(_xlfn.NUMBERVALUE(G32)>0,'质量分析(总分) '!$D$23,'质量分析(总分) '!$D$28) -> 535.86929
A36: 高三上 期末考 | B36: 班级 | C36: 姓名 | D36: 语文 | E36: 数学 | F36: 英语 | G36: 物理 | H36: 化学 | I36: 生物 | J36: 政治 | K36: 历史 | L36: 地理 | M36: 总分
B37: =INDIRECT("'按班级打印'!G"&ROUNDDOWN((ROW()-1)/5,0)+2) -> 1 | C37: =INDIRECT("'按班级打印'!A"&ROUNDDOWN((ROW()-1)/5,0)+2) -> 刘畅 | D37: =INDIRECT("'按班级打印'!M"&ROUNDDOWN((ROW()-1)/5,0)+2) -> 107 | E37: =INDIRECT("'按班级打印'!o"&ROUNDDOWN((ROW()-1)/5,0)+2) -> 112.5 | F37: =INDIRECT("'按班级打印'!q"&ROUNDDOWN((ROW()-1)/5,0)+2) -> 123 | G37: =IF(INDIRECT("'按班级打印'!s"&ROUNDDOWN((ROW()-1)/5,0)+2)>0,INDIRECT("'按班级打印'!s"&ROUNDDOWN((ROW()-1)/5,0)+2),"") -> 70.5 | H37: =IF(INDIRECT("'按班级打印'!w"&ROUNDDOWN((ROW()-1)/5,0)+2)>0,INDIRECT("'按班级打印'!w"&ROUNDDOWN((ROW()-1)/5,0)+2),"") -> 80 | I37: =IF(INDIRECT("'按班级打印'!z"&ROUNDDOWN((ROW()-1)/5,0)+2)>0,INDIRECT("'按班级打印'!z"&ROUNDDOWN((ROW()-1)/5,0)+2),"") -> 82.5 | J37: =IF(INDIRECT("'按班级打印'!ac"&ROUNDDOWN((ROW()-1)/5,0)+2)>0,INDIRECT("'按班级打印'!ac"&ROUNDDOWN((ROW()-1)/5,0)+2),"") | K37: =IF(INDIRECT("'按班级打印'!u"&ROUNDDOWN((ROW()-1)/5,0)+2)>0,INDIRECT("'按班级打印'!u"&ROUNDDOWN((ROW()-1)/5,0)+2),"") | L37: =IF(INDIRECT("'按班级打印'!af"&ROUNDDOWN((ROW()-1)/5,0)+2)>0,INDIRECT("'按班级打印'!af"&ROUNDDOWN((ROW()-1)/5,0)+2),"") | M37: =INDIRECT("'按班级打印'!H"&ROUNDDOWN((ROW()-1)/5,0)+2) -> 575.5
C38: 赋分 | D38: =INDIRECT("'按班级打印'!M"&ROUNDDOWN((ROW()-1)/5,0)+2) -> 107 | E38: =INDIRECT("'按班级打印'!o"&ROUNDDOWN((ROW()-1)/5,0)+2) -> 112.5 | F38: =INDIRECT("'按班级打印'!q"&ROUNDDOWN((ROW()-1)/5,0)+2) -> 123 | G38: =IF(INDIRECT("'按班级打印'!s"&ROUNDDOWN((ROW()-1)/5,0)+2)>0,INDIRECT("'按班级打印'!s"&ROUNDDOWN((ROW()-1)/5,0)+2),"") -> 70.5 | H38: =IF(INDIRECT("'按班级打印'!x"&ROUNDDOWN((ROW()-1)/5,0)+2)>0,INDIRECT("'按班级打印'!x"&ROUNDDOWN((ROW()-1)/5,0)+2),"") -> 93 | I38: =IF(INDIRECT("'按班级打印'!aa"&ROUNDDOWN((ROW()-1)/5,0)+2)>0,INDIRECT("'按班级打印'!aa"&ROUNDDOWN((ROW()-1)/5,0)+2),"") -> 90 | J38: =IF(INDIRECT("'按班级打印'!ad"&ROUNDDOWN((ROW()-1)/5,0)+2)>0,INDIRECT("'按班级打印'!ad"&ROUNDDOWN((ROW()-1)/5,0)+2),"") | K38: =IF(INDIRECT("'按班级打印'!u"&ROUNDDOWN((ROW()-1)/5,0)+2)>0,INDIRECT("'按班级打印'!u"&ROUNDDOWN((ROW()-1)/5,0)+2),"") | L38: =IF(INDIRECT("'按班级打印'!ag"&ROUNDDOWN((ROW()-1)/5,0)+2)>0,INDIRECT("'按班级打印'!ag"&ROUNDDOWN((ROW()-1)/5,0)+2),"") | M38: =INDIRECT("'按班级打印'!I"&ROUNDDOWN((ROW()-1)/5,0)+2) -> 596
A39: =INDIRECT("'按班级打印'!E"&ROUNDDOWN((ROW()-1)/5,0)+2) -> 物理类 | C39: 平均分 | D39: ='质量分析(总分) '!$D$55 -> 105.00061 | E39: ='质量分析(总分) '!$D$82 -> 91.524203 | F39: ='质量分析(总分) '!$D$109 -> 108.86397 | G39: =IF(_xlfn.NUMBERVALUE(G37)>0,'质量分析(总分) '!$D$133,"") -> 62.652143 | H39: =IF(_xlfn.NUMBERVALUE(H37)>0,'质量分析(总分) '!$D$157,"") -> 81.868613 | I39: =IF(_xlfn.NUMBERVALUE(I37)>0,'质量分析(总分) '!$D$180,"") -> 83.367647 | J39: =IF(_xlfn.NUMBERVALUE(J37)>0,'质量分析(总分) '!$D$208,"") | K39: =IF(_xlfn.NUMBERVALUE(K37)>0,'质量分析(总分) '!$D$194,"") | L39: =IF(_xlfn.NUMBERVALUE(L37)>0,'质量分析(总分) '!$D$222,"") | M39: =IF(_xlfn.NUMBERVALUE(G37)>0,'质量分析(总分) '!$D$23,'质量分析(总分) '!$D$28) -> 535.86929
A41: 高三上 期末考 | B41: 班级 | C41: 姓名 | D41: 语文 | E41: 数学 | F41: 英语 | G41: 物理 | H41: 化学 | I41: 生物 | J41: 政治 | K41: 历史 | L41: 地理 | M41: 总分
B42: =INDIRECT("'按班级打印'!G"&ROUNDDOWN((ROW()-1)/5,0)+2) -> 1 | C42: =INDIRECT("'按班级打印'!A"&ROUNDDOWN((ROW()-1)/5,0)+2) -> 吴宇豪 | D42: =INDIRECT("'按班级打印'!M"&ROUNDDOWN((ROW()-1)/5,0)+2) -> 111 | E42: =INDIRECT("'按班级打印'!o"&ROUNDDOWN((ROW()-1)/5,0)+2) -> 104 | F42: =INDIRECT("'按班级打印'!q"&ROUNDDOWN((ROW()-1)/5,0)+2) -> 104 | G42: =IF(INDIRECT("'按班级打印'!s"&ROUNDDOWN((ROW()-1)/5,0)+2)>0,INDIRECT("'按班级打印'!s"&ROUNDDOWN((ROW()-1)/5,0)+2),"") -> 63.5 | H42: =IF(INDIRECT("'按班级打印'!w"&ROUNDDOWN((ROW()-1)/5,0)+2)>0,INDIRECT("'按班级打印'!w"&ROUNDDOWN((ROW()-1)/5,0)+2),"") -> 65 | I42: =IF(INDIRECT("'按班级打印'!z"&ROUNDDOWN((ROW()-1)/5,0)+2)>0,INDIRECT("'按班级打印'!z"&ROUNDDOWN((ROW()-1)/5,0)+2),"") -> 75.5 | J42: =IF(INDIRECT("'按班级打印'!ac"&ROUNDDOWN((ROW()-1)/5,0)+2)>0,INDIRECT("'按班级打印'!ac"&ROUNDDOWN((ROW()-1)/5,0)+2),"") | K42: =IF(INDIRECT("'按班级打印'!u"&ROUNDDOWN((ROW()-1)/5,0)+2)>0,INDIRECT("'按班级打印'!u"&ROUNDDOWN((ROW()-1)/5,0)+2),"") | L42: =IF(INDIRECT("'按班级打印'!af"&ROUNDDOWN((ROW()-1)/5,0)+2)>0,INDIRECT("'按班级打印'!af"&ROUNDDOWN((ROW()-1)/5,0)+2),"") | M42: =INDIRECT("'按班级打印'!H"&ROUNDDOWN((ROW()-1)/5,0)+2) -> 523
C43: 赋分 | D43: =INDIRECT("'按班级打印'!M"&ROUNDDOWN((ROW()-1)/5,0)+2) -> 111 | E43: =INDIRECT("'按班级打印'!o"&ROUNDDOWN((ROW()-1)/5,0)+2) -> 104 | F43: =INDIRECT("'按班级打印'!q"&ROUNDDOWN((ROW()-1)/5,0)+2) -> 104 | G43: =IF(INDIRECT("'按班级打印'!s"&ROUNDDOWN((ROW()-1)/5,0)+2)>0,INDIRECT("'按班级打印'!s"&ROUNDDOWN((ROW()-1)/5,0)+2),"") -> 63.5 | H43: =IF(INDIRECT("'按班级打印'!x"&ROUNDDOWN((ROW()-1)/5,0)+2)>0,INDIRECT("'按班级打印'!x"&ROUNDDOWN((ROW()-1)/5,0)+2),"") -> 87 | I43: =IF(INDIRECT("'按班级打印'!aa"&ROUNDDOWN((ROW()-1)/5,0)+2)>0,INDIRECT("'按班级打印'!aa"&ROUNDDOWN((ROW()-1)/5,0)+2),"") -> 84 | J43: =IF(INDIRECT("'按班级打印'!ad"&ROUNDDOWN((ROW()-1)/5,0)+2)>0,INDIRECT("'按班级打印'!ad"&ROUNDDOWN((ROW()-1)/5,0)+2),"") | K43: =IF(INDIRECT("'按班级打印'!u"&ROUNDDOWN((ROW()-1)/5,0)+2)>0,INDIRECT("'按班级打印'!u"&ROUNDDOWN((ROW()-1)/5,0)+2),"") | L43: =IF(INDIRECT("'按班级打印'!ag"&ROUNDDOWN((ROW()-1)/5,0)+2)>0,INDIRECT("'按班级打印'!ag"&ROUNDDOWN((ROW()-1)/5,0)+2),"") | M43: =INDIRECT("'按班级打印'!I"&ROUNDDOWN((ROW()-1)/5,0)+2) -> 553.5
A44: =INDIRECT("'按班级打印'!E"&ROUNDDOWN((ROW()-1)/5,0)+2) -> 物理类 | C44: 平均分 | D44: ='质量分析(总分) '!$D$55 -> 105.00061 | E44: ='质量分析(总分) '!$D$82 -> 91.524203 | F44: ='质量分析(总分) '!$D$109 -> 108.86397 | G44: =IF(_xlfn.NUMBERVALUE(G42)>0,'质量分析(总分) '!$D$133,"") -> 62.652143 | H44: =IF(_xlfn.NUMBERVALUE(H42)>0,'质量分析(总分) '!$D$157,"") -> 81.868613 | I44: =IF(_xlfn.NUMBERVALUE(I42)>0,'质量分析(总分) '!$D$180,"") -> 83.367647 | J44: =IF(_xlfn.NUMBERVALUE(J42)>0,'质量分析(总分) '!$D$208,"") | K44: =IF(_xlfn.NUMBERVALUE(K42)>0,'质量分析(总分) '!$D$194,"") | L44: =IF(_xlfn.NUMBERVALUE(L42)>0,'质量分析(总分) '!$D$222,"") | M44: =IF(_xlfn.NUMBERVALUE(G42)>0,'质量分析(总分) '!$D$23,'质量分析(总分) '!$D$28) -> 535.86929
A46: 高三上 期末考 | B46: 班级 | C46: 姓名 | D46: 语文 | E46: 数学 | F46: 英语 | G46: 物理 | H46: 化学 | I46: 生物 | J46: 政治 | K46: 历史 | L46: 地理 | M46: 总分
B47: =INDIRECT("'按班级打印'!G"&ROUNDDOWN((ROW()-1)/5,0)+2) -> 1 | C47: =INDIRECT("'按班级打印'!A"&ROUNDDOWN((ROW()-1)/5,0)+2) -> 林津如 | D47: =INDIRECT("'按班级打印'!M"&ROUNDDOWN((ROW()-1)/5,0)+2) -> 114.5 | E47: =INDIRECT("'按班级打印'!o"&ROUNDDOWN((ROW()-1)/5,0)+2) -> 89.5 | F47: =INDIRECT("'按班级打印'!q"&ROUNDDOWN((ROW()-1)/5,0)+2) -> 111 | G47: =IF(INDIRECT("'按班级打印'!s"&ROUNDDOWN((ROW()-1)/5,0)+2)>0,INDIRECT("'按班级打印'!s"&ROUNDDOWN((ROW()-1)/5,0)+2),"") -> 60 | H47: =IF(INDIRECT("'按班级打印'!w"&ROUNDDOWN((ROW()-1)/5,0)+2)>0,INDIRECT("'按班级打印'!w"&ROUNDDOWN((ROW()-1)/5,0)+2),"") -> 76 | I47: =IF(INDIRECT("'按班级打印'!z"&ROUNDDOWN((ROW()-1)/5,0)+2)>0,INDIRECT("'按班级打印'!z"&ROUNDDOWN((ROW()-1)/5,0)+2),"") -> 77.5 | J47: =IF(INDIRECT("'按班级打印'!ac"&ROUNDDOWN((ROW()-1)/5,0)+2)>0,INDIRECT("'按班级打印'!ac"&ROUNDDOWN((ROW()-1)/5,0)+2),"") | K47: =IF(INDIRECT("'按班级打印'!u"&ROUNDDOWN((ROW()-1)/5,0)+2)>0,INDIRECT("'按班级打印'!u"&ROUNDDOWN((ROW()-1)/5,0)+2),"") | L47: =IF(INDIRECT("'按班级打印'!af"&ROUNDDOWN((ROW()-1)/5,0)+2)>0,INDIRECT("'按班级打印'!af"&ROUNDDOWN((ROW()-1)/5,0)+2),"") | M47: =INDIRECT("'按班级打印'!H"&ROUNDDOWN((ROW()-1)/5,0)+2) -> 528.5
C48: 赋分 | D48: =INDIRECT("'按班级打印'!M"&ROUNDDOWN((ROW()-1)/5,0)+2) -> 114.5 | E48: =INDIRECT("'按班级打印'!o"&ROUNDDOWN((ROW()-1)/5,0)+2) -> 89.5 | F48: =INDIRECT("'按班级打印'!q"&ROUNDDOWN((ROW()-1)/5,0)+2) -> 111 | G48: =IF(INDIRECT("'按班级打印'!s"&ROUNDDOWN((ROW()-1)/5,0)+2)>0,INDIRECT("'按班级打印'!s"&ROUNDDOWN((ROW()-1)/5,0)+2),"") -> 60 | H48: =IF(INDIRECT("'按班级打印'!x"&ROUNDDOWN((ROW()-1)/5,0)+2)>0,INDIRECT("'按班级打印'!x"&ROUNDDOWN((ROW()-1)/5,0)+2),"") -> 91 | I48: =IF(INDIRECT("'按班级打印'!aa"&ROUNDDOWN((ROW()-1)/5,0)+2)>0,INDIRECT("'按班级打印'!aa"&ROUNDDOWN((ROW()-1)/5,0)+2),"") -> 87 | J48: =IF(INDIRECT("'按班级打印'!ad"&ROUNDDOWN((ROW()-1)/5,0)+2)>0,INDIRECT("'按班级打印'!ad"&ROUNDDOWN((ROW()-1)/5,0)+2),"") | K48: =IF(INDIRECT("'按班级打印'!u"&ROUNDDOWN((ROW()-1)/5,0)+2)>0,INDIRECT("'按班级打印'!u"&ROUNDDOWN((ROW()-1)/5,0)+2),"") | L48: =IF(INDIRECT("'按班级打印'!ag"&ROUNDDOWN((ROW()-1)/5,0)+2)>0,INDIRECT("'按班级打印'!ag"&ROUNDDOWN((ROW()-1)/5,0)+2),"") | M48: =INDIRECT("'按班级打印'!I"&ROUNDDOWN((ROW()-1)/5,0)+2) -> 553
A49: =INDIRECT("'按班级打印'!E"&ROUNDDOWN((ROW()-1)/5,0)+2) -> 物理类 | C49: 平均分 | D49: ='质量分析(总分) '!$D$55 -> 105.00061 | E49: ='质量分析(总分) '!$D$82 -> 91.524203 | F49: ='质量分析(总分) '!$D$109 -> 108.86397 | G49: =IF(_xlfn.NUMBERVALUE(G47)>0,'质量分析(总分) '!$D$133,"") -> 62.652143 | H49: =IF(_xlfn.NUMBERVALUE(H47)>0,'质量分析(总分) '!$D$157,"") -> 81.868613 | I49: =IF(_xlfn.NUMBERVALUE(I47)>0,'质量分析(总分) '!$D$180,"") -> 83.367647 | J49: =IF(_xlfn.NUMBERVALUE(J47)>0,'质量分析(总分) '!$D$208,"") | K49: =IF(_xlfn.NUMBERVALUE(K47)>0,'质量分析(总分) '!$D$194,"") | L49: =IF(_xlfn.NUMBERVALUE(L47)>0,'质量分析(总分) '!$D$222,"") | M49: =IF(_xlfn.NUMBERVALUE(G47)>0,'质量分析(总分) '!$D$23,'质量分析(总分) '!$D$28) -> 535.86929
...

Sheet 按班级打印
A1: 姓名 | B1: 考号 | C1: 学号 | D1: 学籍校 | E1: 科类 | F1: 备注 | G1: 班级 | H1: 总分 | I1: 赋分总分 | J1: 赋分总分排名 | K1: 进退步 | L1: 联考排名 | M1: 语文 | N1: 语文排名 | O1: 数学 | P1: 数学排名 | Q1: 英语 | R1: 英语排名 | S1: 物理 | T1: 物理排名 | U1: 历史 | V1: 历史排名 | W1: 化学 | X1: 化学赋分 | Y1: 化学排名 | Z1: 生物 | AA1: 生物赋分 | AB1: 生物排名 | AC1: 政治 | AD1: 政治赋分 | AE1: 政治排名 | AF1: 地理 | AG1: 地理赋分 | AH1: 地理排名 | AI1: 选科 | AJ1: 座号 | AK1: 化学教学班名称 | AL1: 生物教学班名称 | AM1: 政治教学班名称 | AN1: 地理教学班名称 | AO1: 上月考1排名 | AP1: 上月考2排名 | AQ1: 上月考4排名 | AR1: 上月考5排名 | AS1: 上半期考排名 | AT1: 上期末考排名
A2: 郑智文 | B2: 1315230101 | C2: 32370010005 | D2: 一中 | E2: 物理类 | G2: 1 | H2: 475 | I2: 509.5 | J2: 496 | K2: -55 | L2: 2947 | M2: 105 | N2: 406 | O2: 70 | P2: 713 | Q2: 119 | R2: 212 | S2: 66.5 | T2: 292 | W2: 50.5 | X2: 76 | Y2: 516 | Z2: 64 | AA2: 73 | AB2: 417 | AI2: 物化生 | AJ2: 1 | AO2: 433 | AP2: 416 | AQ2: 437 | AR2: 441 | AS2: 192 | AT2: 496
A3: 林慧 | B3: 1315230102 | C3: 32370010014 | D3: 一中 | E3: 物理类 | G3: 1 | H3: 485.5 | I3: 517 | J3: 468 | K3: 161 | L3: 2630 | M3: 89 | N3: 785 | O3: 114 | P3: 69 | Q3: 87 | R3: 746 | S3: 60 | T3: 413 | W3: 62 | X3: 85 | Y3: 312 | Z3: 73.5 | AA3: 82 | AB3: 273 | AI3: 物化生 | AJ3: 2 | AO3: 574 | AP3: 561 | AQ3: 522 | AR3: 629 | AS3: 502 | AT3: 468
A4: 钟林斌 | B4: 1315230103 | C4: 32370010018 | D4: 一中 | E4: 物理类 | G4: 1 | H4: 537 | I4: 566 | J4: 204 | K4: -81 | L4: 1002 | M4: 100.5 | N4: 584 | O4: 108.5 | P4: 110 | Q4: 116.5 | R4: 274 | S4: 61.5 | T4: 381 | W4: 65.5 | X4: 87 | Y4: 239 | Z4: 84.5 | AA4: 92 | AB4: 66 | AI4: 物化生 | AJ4: 3 | AO4: 144 | AP4: 197 | AQ4: 199 | AR4: 123 | AS4: 171 | AT4: 204
A5: 占谨豪 | B5: 1315230104 | C5: 32370010057 | D5: 一中 | E5: 物理类 | G5: 1 | H5: 450 | I5: 485 | J5: 577 | K5: 8 | L5: 4141 | M5: 105 | N5: 406 | O5: 78.5 | P5: 643 | Q5: 85.5 | R5: 755 | S5: 62 | T5: 373 | W5: 50 | X5: 76 | Y5: 523 | Z5: 69 | AA5: 78 | AB5: 354 | AI5: 物化生 | AJ5: 4 | AO5: 600 | AP5: 413 | AQ5: 220 | AR5: 585 | AS5: 382 | AT5: 577
A6: 雷雯颖 | B6: 1315230105 | C6: 32370010102 | D6: 一中 | E6: 物理类 | G6: 1 | H6: 495 | I6: 527.5 | J6: 404 | K6: 81 | L6: 2205 | M6: 102 | N6: 529 | O6: 79.5 | P6: 631 | Q6: 111.5 | R6: 371 | S6: 67.5 | T6: 275 | W6: 56 | X6: 80 | Y6: 426 | Z6: 78.5 | AA6: 87 | AB6: 181 | AI6: 物化生 | AJ6: 5 | AO6: 421 | AP6: 478 | AQ6: 569 | AR6: 485 | AS6: 491 | AT6: 404
A7: 陈静怡 | B7: 1315230106 | C7: 32370010119 | D7: 一中 | E7: 物理类 | G7: 1 | H7: 531 | I7: 562 | J7: 230 | K7: 147 | L7: 1113 | M7: 101.5 | N7: 544 | O7: 96.5 | P7: 342 | Q7: 113 | R7: 337 | S7: 77 | T7: 124 | W7: 65 | X7: 87 | Y7: 248 | Z7: 78 | AA7: 87 | AB7: 195 | AI7: 物化生 | AJ7: 6 | AO7: 394 | AP7: 342 | AQ7: 317 | AR7: 377 | AS7: 431 | AT7: 230
A8: 吴冠轩 | B8: 1315230107 | C8: 32370010130 | D8: 一中 | E8: 物理类 | G8: 1 | H8: 546.5 | I8: 574.5 | J8: 158 | K8: 16 | L8: 795 | M8: 106 | N8: 361 | O8: 107 | P8: 142 | Q8: 107.5 | R8: 463 | S8: 78 | T8: 109 | W8: 69.5 | X8: 89 | Y8: 165 | Z8: 78.5 | AA8: 87 | AB8: 181 | AI8: 物化生 | AJ8: 7 | AO8: 271 | AP8: 262 | AQ8: 281 | AR8: 174 | AS8: 375 | AT8: 158
A9: 刘畅 | B9: 1315230108 | C9: 32370010148 | D9: 一中 | E9: 物理类 | G9: 1 | H9: 575.5 | I9: 596 | J9: 100 | K9: -26 | L9: 416 | M9: 107 | N9: 325 | O9: 112.5 | P9: 84 | Q9: 123 | R9: 123 | S9: 70.5 | T9: 217 | W9: 80 | X9: 93 | Y9: 40 | Z9: 82.5 | AA9: 90 | AB9: 99 | AI9: 物化生 | AJ9: 8 | AO9: 49 | AP9: 79 | AQ9: 72 | AR9: 74 | AS9: 47 | AT9: 100
A10: 吴宇豪 | B10: 1315230109 | C10: 32370010198 | D10: 一中 | E10: 物理类 | G10: 1 | H10: 523 | I10: 553.5 | J10: 270 | K10: 27 | L10: 1349 | M10: 111 | N10: 172 | O10: 104 | P10: 193 | Q10: 104 | R10: 541 | S10: 63.5 | T10: 342 | W10: 65 | X10: 87 | Y10: 248 | Z10: 75.5 | AA10: 84 | AB10: 235 | AI10: 物化生 | AJ10: 9 | AO10: 227 | AP10: 356 | AQ10: 269 | AR10: 297 | AS10: 283 | AT10: 270
A11: 林津如 | B11: 1315230110 | C11: 32370010204 | D11: 一中 | E11: 物理类 | G11: 1 | H11: 528.5 | I11: 553 | J11: 274 | K11: 203 | L11: 1371 | M11: 114.5 | N11: 74 | O11: 89.5 | P11: 463 | Q11: 111 | R11: 385 | S11: 60 | T11: 413 | W11: 76 | X11: 91 | Y11: 71 | Z11: 77.5 | AA11: 87 | AB11: 204 | AI11: 物化生 | AJ11: 10 | AO11: 325 | AP11: 492 | AQ11: 374 | AR11: 477 | AS11: 325 | AT11: 274
A12: 范佳馨 | B12: 1315230111 | C12: 32370010212 | D12: 一中 | E12: 物理类 | G12: 1 | H12: 552.25 | I12: 580.5 | J12: 139 | K12: 50 | L12: 663 | M12: 118.5 | N12: 28 | O12: 104 | P12: 193 | Q12: 121 | R12: 168 | S12: 60 | T12: 413 | W12: 69.5 | X12: 89 | Y12: 165 | Z12: 79.25 | AA12: 88 | AB12: 170 | AI12: 物化生 | AJ12: 11 | AO12: 309 | AP12: 118 | AQ12: 199 | AR12: 189 | AS12: 346 | AT12: 139
A13: 林铭昊 | B13: 1315230112 | C13: 32370010236 | D13: 一中 | E13: 物理类 | G13: 1 | H13: 542 | I13: 571 | J13: 179 | K13: 215 | L13: 869 | M13: 93.5 | N13: 754 | O13: 113.5 | P13: 77 | Q13: 107 | R13: 474 | S13: 81 | T13: 76 | W13: 68 | X13: 88 | Y13: 197 | Z13: 79 | AA13: 88 | AB13: 171 | AI13: 物化生 | AJ13: 12 | AO13: 437 | AP13: 368 | AQ13: 422 | AR13: 394 | AS13: 346 | AT13: 179
... A21: 阮奕杰 | B21: 1315230120 | C21: 32370010428 | D21: 一中 | E21: 物理类 | G21: 1 | H21: 526.5 | I21: 558 | J21: 249 | K21: -79 | L21: 1224 | M21: 109 | N21: 245 | O21: 104 | P21: 193 | Q21: 112.5 | R21: 350 | S21: 65.5 | T21: 311 | W21: 63 | X21: 86 | Y21: 297 | Z21: 72.5 | AA21: 81 | AB21: 289 | AI21: 物化生 | AJ21: 20 | AO21: 241 | AP21: 181 | AQ21: 140 | AR21: 170 | AS21: 206 | AT21: 249
A22: 詹文杰 | B22: 1315230121 | C22: 32370010429 | D22: 一中 | E22: 物理类 | G22: 1 | H22: 533 | I22: 565.5 | J22: 209 | K22: -26 | L22: 1019 | M22: 105 | N22: 406 | O22: 108.5 | P22: 110 | Q22: 121.5 | R22: 152 | S22: 61.5 | T22: 381 | W22: 60 | X22: 83 | Y22: 352 | Z22: 76.5 | AA22: 86 | AB22: 222 | AI22: 物化生 | AJ22: 21 | AP22: 185 | AQ22: 95 | AR22: 183 | AS22: 88 | AT22: 209
A23: 毕禾 | B23: 1315230122 | C23: 32370010457 | D23: 一中 | E23: 物理类 | G23: 1 | H23: 500.5 | I23: 534 | J23: 372 | K23: -125 | L23: 1978 | M23: 102.5 | N23: 511 | O23: 107 | P23: 142 | Q23: 115 | R23: 294 | S23: 53.5 | T23: 510 | W23: 58 | X23: 82 | Y23: 385 | Z23: 64.5 | AA23: 74 | AB23: 415 | AI23: 物化生 | AJ23: 22 | AO23: 440 | AP23: 339 | AQ23: 480 | AR23: 247 | AS23: 494 | AT23: 372
A24: 林开馨 | B24: 1315230123 | C24: 32370010470 | D24: 一中 | E24: 物理类 | G24: 1 | H24: 453.5 | I24: 488.5 | J24: 569 | K24: -37 | L24: 3946 | M24: 100.5 | N24: 584 | O24: 99 | P24: 285 | Q24: 94 | R24: 687 | S24: 33 | T24: 667 | W24: 49 | X24: 75 | Y24: 534 | Z24: 78 | AA24: 87 | AB24: 195 | AI24: 物化生 | AJ24: 23 | AO24: 494 | AP24: 555 | AQ24: 549 | AR24: 532 | AS24: 566 | AT24: 569
A25: 卓胤霖 | B25: 1315230124 | C25: 32370010510 | D25: 一中 | E25: 物理类 | G25: 1 | H25: 537 | I25: 567.5 | J25: 196 | K25: 144 | L25: 961 | M25: 105.5 | N25: 382 | O25: 99.5 | P25: 270 | Q25: 125.5 | R25: 89 | S25: 68 | T25: 269 | W25: 65 | X25: 87 | Y25: 248 | Z25: 73.5 | AA25: 82 | AB25: 273 | AI25: 物化生 | AJ25: 24 | AO25: 202 | AP25: 272 | AQ25: 127 | AR25: 340 | AS25: 181 | AT25: 196
A26: 谢承烨 | B26: 1315230125 | C26: 32370010534 | D26: 一中 | E26: 物理类 | G26: 1 | H26: 431 | I26: 467 | J26: 627 | K26: 17 | L26: 5164 | M26: 108.5 | N26: 258 | O26: 85.5 | P26: 530 | Q26: 101 | R26: 592 | S26: 34 | T26: 665 | W26: 41 | X26: 68 | Y26: 615 | Z26: 61 | AA26: 70 | AB26: 436 | AI26: 物化生 | AJ26: 25 | AO26: 550 | AP26: 668 | AQ26: 637 | AR26: 644 | AS26: 659 | AT26: 627
A27: 郭仕涛 | B27: 1315230126 | C27: 32370010546 | D27: 一中 | E27: 物理类 | G27: 1 | H27: 485.5 | I27: 519 | J27: 450 | K27: -4 | L27: 2538 | M27: 97.5 | N27: 678 | O27: 79.5 | P27: 631 | Q27: 112 | R27: 360 | S27: 71 | T27: 205 | W27: 57.5 | X27: 82 | Y27: 393 | Z27: 68 | AA27: 77 | AB27: 372 | AI27: 物化生 | AJ27: 26 | AO27: 403 | AP27: 681 | AQ27: 456 | AR27: 446 | AS27: 522 | AT27: 450
A28: 刘文鼎 | B28: 1315230127 | C28: 32370010595 | D28: 一中 | E28: 物理类 | G28: 1 | H28: 535 | I28: 565.5 | J28: 209 | K28: 14 | L28: 1019 | M28: 98.5 | N28: 653 | O28: 106 | P28: 160 | Q28: 108 | R28: 453 | S28: 80 | T28: 85 | W28: 65.5 | X28: 87 | Y28: 239 | Z28: 77 | AA28: 86 | AB28: 212 | AI28: 物化生 | AJ28: 27 | AO28: 250 | AP28: 382 | AQ28: 190 | AR28: 223 | AS28: 401 | AT28: 209
A29: 吴钰婷 | B29: 1315230128 | C29: 32370010600 | D29: 一中 | E29: 物理类 | G29: 1 | H29: 563.5 | I29: 589.5 | J29: 113 | K29: 13 | L29: 499 | M29: 108.5 | N29: 258 | O29: 114 | P29: 69 | Q29: 113.5 | R29: 327 | S29: 75.5 | T29: 151 | W29: 71 | X29: 89 | Y29: 149 | Z29: 81 | AA29: 89 | AB29: 132 | AI29: 物化生 | AJ29: 28 | AO29: 37 | AP29: 72 | AQ29: 131 | AR29: 126 | AS29: 121 | AT29: 113
A30: 沈芝含 | B30: 1315230129 | C30: 32370010624 | D30: 一中 | E30: 物理类 | G30: 1 | H30: 547 | I30: 574.5 | J30: 158 | K30: -32 | L30: 795 | M30: 113 | N30: 112 | O30: 107 | P30: 142 | Q30: 119.5 | R30: 200 | S30: 57 | T30: 462 | W30: 70 | X30: 89 | Y30: 159 | Z30: 80.5 | AA30: 89 | AB30: 144 | AI30: 物化生 | AJ30: 29 | AO30: 171 | AP30: 181 | AQ30: 79 | AR30: 126 | AS30: 52 | AT30: 158
A31: 陈林榕 | B31: 1315230130 | C31: 32370010628 | D31: 一中 | E31: 物理类 | G31: 1 | H31: 573.5 | I31: 591.5 | J31: 109 | K31: -58 | L31: 466 | M31: 107.5 | N31: 300 | O31: 101.5 | P31: 235 | Q31: 121.5 | R31: 152 | S31: 73 | T31: 181 | W31: 82 | X31: 94 | Y31: 29 | Z31: 88 | AA31: 94 | AB31: 28 | AI31: 物化生 | AJ31: 30 | AO31: 55 | AP31: 88 | AQ31: 111 | AR31: 51 | AS31: 80 | AT31: 109
A32: 叶柏坤 | B32: 1315230131 | C32: 32370010641 | D32: 一中 | E32: 物理类 | G32: 1 | H32: 496.75 | I32: 531.25 | J32: 384 | K32: 28 | L32: 2081 | M32: 113 | N32: 112 | O32: 107.5 | P32: 129 | Q32: 90 | R32: 728 | S32: 66.75 | T32: 291 | W32: 55 | X32: 80 | Y32: 444 | Z32: 64.5 | AA32: 74 | AB32: 415 | AI32: 物化生 | AJ32: 31 | AO32: 534 | AP32: 496 | AQ32: 528 | AR32: 412 | AS32: 502 | AT32: 384
A33: 林至勤 | B33: 1315230132 | C33: 32370010658 | D33: 一中 | E33: 物理类 | G33: 1 | H33: 534 | I33: 563 | J33: 223 | K33: 44 | L33: 1086 | M33: 106.5 | N33: 346 | O33: 104 | P33: 193 | Q33: 111 | R33: 385 | S33: 74.5 | T33: 159 | W33: 69 | X33: 89 | Y33: 170 | Z33: 69 | AA33: 78 | AB33: 354 | AI33: 物化生 | AJ33: 32 | AO33: 127 | AP33: 216 | AQ33: 196 | AR33: 267 | AS33: 195 | AT33: 223
A34: 赖妍君 | B34: 1315230133 | C34: 32370010684 | D34: 一中 | E34: 物理类 | G34: 1 | H34: 401.5 | I34: 438.5 | J34: 666 | K34: -23 | L34: 6854 | M34: 101 | N34: 561 | O34: 71 | P34: 704 | Q34: 95.5 | R34: 672 | S34: 31 | T34: 672 | W34: 40.5 | X34: 68 | Y34: 619 | Z34: 62.5 | AA34: 72 | AB34: 429 | AI34: 物化生 | AJ34: 33 | AO34: 651 | AP34: 654 | AQ34: 666 | AR34: 643 | AS34: 673 | AT34: 666
... A64: 阮禹诚 | B64: 1315230216 | C64: 32370010251 | D64: 一中 | E64: 物理类 | G64: 2 | H64: 486.5 | I64: 519 | J64: 450 | K64: -115 | L64: 2538 | M64: 107.5 | N64: 300 | O64: 82 | P64: 597 | Q64: 101.5 | R64: 583 | S64: 61 | T64: 396 | W64: 56 | X64: 80 | Y64: 426 | Z64: 78.5 | AA64: 87 | AB64: 181 | AI64: 物化生 | AJ64: 16 | AO64: 377 | AP64: 458 | AQ64: 429 | AR64: 335 | AS64: 272 | AT64: 450
A65: 林晓轩 | B65: 1315230217 | C65: 32370010289 | D65: 一中 | E65: 物理类 | G65: 2 | H65: 459 | I65: 493.5 | J65: 549 | L65: 3686 | M65: 101 | N65: 561 | O65: 84.5 | P65: 553 | Q65: 99 | R65: 617 | S65: 58 | T65: 447 | W65: 53.5 | X65: 79 | Y65: 471 | Z65: 63 | AA65: 72 | AB65: 423 | AI65: 物化生 | AJ65: 17 | AO65: 534 | AP65: 468 | AQ65: 596 | AS65: 464 | AT65: 549
A66: 刘兆彬 | B66: 1315230218 | C66: 32370010304 | D66: 一中 | E66: 物理类 | G66: 2 | H66: 527 | I66: 554.5 | J66: 266 | K66: 43 | L66: 1319 | M66: 100.5 | N66: 584 | O66: 98.5 | P66: 298 | Q66: 122.5 | R66: 130 | S66: 66 | T66: 301 | W66: 71 | X66: 89 | Y66: 149 | Z66: 68.5 | AA66: 78 | AB66: 366 | AI66: 物化生 | AJ66: 18 | AO66: 328 | AP66: 174 | AQ66: 215 | AR66: 309 | AS66: 257 | AT66: 266
A67: 林兰珂 | B67: 1315230220 | C67: 32370010369 | D67: 一中 | E67: 物理类 | G67: 2 | H67: 486 | I67: 519.5 | J67: 447 | K67: 99 | L67: 2508 | M67: 90 | N67: 781 | O67: 100.5 | P67: 253 | Q67: 97.5 | R67: 652 | S67: 69.5 | T67: 241 | W67: 55 | X67: 80 | Y67: 444 | Z67: 73.5 | AA67: 82 | AB67: 273 | AI67: 物化生 | AJ67: 20 | AO67: 544 | AP67: 394 | AQ67: 328 | AR67: 546 | AS67: 471 | AT67: 447
A68: 薛欧祺 | B68: 1315230221 | C68: 32370010373 | D68: 一中 | E68: 物理类 | G68: 2 | H68: 552.5 | I68: 577 | J68: 149 | K68: -44 | L68: 737 | M68: 111.5 | N68: 155 | O68: 92 | P68: 419 | Q68: 120.5 | R68: 180 | S68: 76 | T68: 142 | W68: 76.5 | X68: 92 | Y68: 66 | Z68: 76 | AA68: 85 | AB68: 231 | AI68: 物化生 | AJ68: 21 | AO68: 190 | AP68: 85 | AQ68: 228 | AR68: 105 | AS68: 229 | AT68: 149
A69: 张越翔 | B69: 1315230222 | C69: 32370010376 | D69: 一中 | E69: 物理类 | G69: 2 | H69: 488 | I69: 516.5 | J69: 472 | K69: -60 | L69: 2654 | M69: 100.5 | N69: 584 | O69: 75 | P69: 675 | Q69: 99 | R69: 617 | S69: 70 | T69: 226 | W69: 68.5 | X69: 88 | Y69: 182 | Z69: 75 | AA69: 84 | AB69: 248 | AI69: 物化生 | AJ69: 22 | AO69: 376 | AP69: 280 | AQ69: 325 | AR69: 412 | AS69: 375 | AT69: 472
A70: 张耘通 | B70: 1315230223 | C70: 32370010389 | D70: 一中 | E70: 物理类 | G70: 2 | H70: 481.5 | I70: 512.5 | J70: 485 | K70: -163 | L70: 2818 | M70: 94.5 | N70: 745 | O70: 91 | P70: 436 | Q70: 96 | R70: 667 | S70: 56 | T70: 473 | W70: 62 | X70: 85 | Y70: 312 | Z70: 82 | AA70: 90 | AB70: 111 | AI70: 物化生 | AJ70: 23 | AO70: 281 | AP70: 160 | AQ70: 354 | AR70: 322 | AS70: 418 | AT70: 485
A71: 王子浩 | B71: 1315230224 | C71: 32370010391 | D71: 一中 | E71: 物理类 | G71: 2 | H71: 492 | I71: 521 | J71: 439 | K71: -126 | L71: 2454 | M71: 105 | N71: 406 | O71: 85 | P71: 541 | Q71: 101 | R71: 592 | S71: 54 | T71: 503 | W71: 68 | X71: 88 | Y71: 197 | Z71: 79 | AA71: 88 | AB71: 171 | AI71: 物化生 | AJ71: 24 | AO71: 382 | AP71: 447 | AQ71: 260 | AR71: 313 | AS71: 466 | AT71: 439
A72: 苏芝宁 | B72: 1315230225 | C72: 32370010423 | D72: 一中 | E72: 物理类 | G72: 2 | H72: 481 | I72: 515.5 | J72: 475 | K72: 130 | L72: 2696 | M72: 108.5 | N72: 258 | O72: 88.5 | P72: 481 | Q72: 101.5 | R72: 583 | S72: 56 | T72: 473 | W72: 53.5 | X72: 79 | Y72: 471 | Z72: 73 | AA72: 82 | AB72: 281 | AI72: 物化生 | AJ72: 25 | AO72: 473 | AP72: 588 | AQ72: 647 | AR72: 605 | AS72: 445 | AT72: 475
A73: 刘晏祯 | B73: 1315230226 | C73: 32370010465 | D73: 一中 | E73: 物理类 | G73: 2 | H73: 487 | I73: 519.5 | J73: 447 | K73: 80 | L73: 2508 | M73: 107 | N73: 325 | O73: 95.5 | P73: 357 | Q73: 115.5 | R73: 288 | S73: 49.5 | T73: 556 | W73: 60 | X73: 83 | Y73: 352 | Z73: 59.5 | AA73: 69 | AB73: 444 | AI73: 物化生 | AJ73: 26 | AO73: 524 | AP73: 584 | AQ73: 470 | AR73: 527 | AS73: 545 | AT73: 447
A74: 陈奕斌 | B74: 1315230227 | C74: 32370010484 | D74: 一中 | E74: 物理类 | G74: 2 | H74: 454 | I74: 487 | J74: 571 | K74: -192 | L74: 4023 | M74: 102.5 | N74: 511 | O74: 81 | P74: 615 | Q74: 98.5 | R74: 627 | S74: 42 | T74: 623 | W74: 60.5 | X74: 84 | Y74: 341 | Z74: 69.5 | AA74: 79 | AB74: 346 | AI74: 物化生 | AJ74: 27 | AO74: 512 | AP74: 568 | AQ74: 561 | AR74: 379 | AS74: 445 | AT74: 571
A75: 李增炜 | B75: 1315230228 | C75: 32370010539 | D75: 一中 | E75: 物理类 | G75: 2 | H75: 506.5 | I75: 537.5 | J75: 357 | K75: 45 | L75: 1868 | M75: 114 | N75: 84 | O75: 84 | P75: 568 | Q75: 114 | R75: 313 | S75: 62.5 | T75: 362 | W75: 65 | X75: 87 | Y75: 248 | Z75: 67 | AA75: 76 | AB75: 392 | AI75: 物化生 | AJ75: 28 | AO75: 373 | AP75: 281 | AQ75: 302 | AR75: 402 | AS75: 276 | AT75: 357
A76: 薛皓仁 | B76: 1315230229 | C76: 32370010556 | D76: 一中 | E76: 物理类 | G76: 2 | H76: 511.5 | I76: 545 | J76: 314 | K76: -1 | L76: 1605 | M76: 105.5 | N76: 382 | O76: 105 | P76: 178 | Q76: 113.5 | R76: 327 | S76: 70 | T76: 226 | W76: 58 | X76: 82 | Y76: 385 | Z76: 59.5 | AA76: 69 | AB76: 444 | AI76: 物化生 | AJ76: 29 | AO76: 437 | AP76: 251 | AR76: 313 | AS76: 318 | AT76: 314
...

Sheet 总分(全体)
A1: 姓名 | B1: 考号 | C1: 学号 | D1: 学籍校 | E1: 科类 | F1: 备注 | G1: 班级 | H1: 总分 | I1: 赋分总分 | J1: 赋分总分排名 | K1: 进退步 | L1: 联考排名 | M1: 语文 | N1: 语文排名 | O1: 数学 | P1: 数学排名 | Q1: 英语 | R1: 英语排名 | S1: 物理 | T1: 物理排名 | U1: 历史 | V1: 历史排名 | W1: 化学 | X1: 化学赋分 | Y1: 化学排名 | Z1: 生物 | AA1: 生物赋分 | AB1: 生物排名 | AC1: 政治 | AD1: 政治赋分 | AE1: 政治排名 | AF1: 地理 | AG1: 地理赋分 | AH1: 地理排名 | AI1: 选科 | AJ1: 座号 | AK1: 化学教学班名称 | AL1: 生物教学班名称 | AM1: 政治教学班名称 | AN1: 地理教学班名称 | AO1: 上月考1排名 | AP1: 上月考2排名 | AQ1: 上月考4排名 | AR1: 上月考5排名 | AS1: 上半期考排名 | AT1: 上期末考排名
A2: 钟亿杨 | B2: 1315231925 | C2: 32370010581 | D2: 一中 | E2: 物理类 | G2: 19 | H2: 646 | I2: 669.5 | J2: 1 | K2: 3 | L2: 2 | M2: 115 | N2: 66 | O2: 131.5 | P2: 3 | Q2: 136 | R2: 3 | S2: 99 | T2: 2 | W2: 71.5 | X2: 90 | Y2: 144 | Z2: 93 | AA2: 98 | AB2: 4 | AI2: 物化生 | AJ2: 25 | AO2: 1 | AP2: 3 | AQ2: 1 | AR2: 4 | AS2: 11 | AT2: 1
A3: 吴凯杰 | B3: 1315231916 | C3: 32370010490 | D3: 一中 | E3: 物理类 | G3: 19 | H3: 631 | I3: 649 | J3: 2 | K3: 11 | L3: 23 | M3: 118.5 | N3: 28 | O3: 117.5 | P3: 46 | Q3: 132.5 | R3: 21 | S3: 94.5 | T3: 6 | W3: 83.5 | X3: 94 | Y3: 21 | Z3: 84.5 | AA3: 92 | AB3: 66 | AI3: 物化生 | AJ3: 16 | AO3: 15 | AP3: 1 | AQ3: 2 | AR3: 13 | AS3: 4 | AT3: 2
A4: 王紫儒 | B4: 1315231910 | C4: 32370010278 | D4: 一中 | E4: 物理类 | G4: 19 | H4: 629 | I4: 648.5 | J4: 3 | K4: 24 | L4: 25 | M4: 119 | N4: 21 | O4: 119.5 | P4: 33 | Q4: 131 | R4: 29 | S4: 91 | T4: 17 | W4: 79 | X4: 93 | Y4: 50 | Z4: 89.5 | AA4: 95 | AB4: 16 | AI4: 物化生 | AJ4: 10 | AO4: 12 | AP4: 8 | AQ4: 18 | AR4: 27 | AS4: 29 | AT4: 3
A5: 缪轩 | B5: 1315231931 | C5: 32370010699 | D5: 一中 | E5: 物理类 | G5: 19 | H5: 631.5 | I5: 646.5 | J5: 4 | K5: 8 | L5: 28 | M5: 113.5 | N5: 101 | O5: 120 | P5: 26 | Q5: 133 | R5: 12 | S5: 94 | T5: 8 | W5: 92 | X5: 98 | Y5: 2 | Z5: 79 | AA5: 88 | AB5: 171 | AI5: 物化生 | AJ5: 31 | AO5: 29 | AP5: 16 | AQ5: 16 | AR5: 12 | AS5: 14 | AT5: 4
A6: 王铮文 | B6: 1315231924 | C6: 32370010573 | D6: 一中 | E6: 物理类 | G6: 19 | H6: 622.5 | I6: 646.5 | J6: 4 | K6: 25 | L6: 28 | M6: 119 | N6: 21 | O6: 137.5 | P6: 1 | Q6: 123 | R6: 123 | S6: 85 | T6: 42 | W6: 74 | X6: 91 | Y6: 110 | Z6: 84 | AA6: 91 | AB6: 75 | AI6: 物化生 | AJ6: 24 | AO6: 18 | AP6: 67 | AQ6: 46 | AR6: 29 | AS6: 63 | AT6: 4
A7: 谢政良 | B7: 1315231010 | C7: 32370010134 | D7: 一中 | E7: 物理类 | G7: 10 | H7: 625.5 | I7: 644 | J7: 6 | K7: 18 | L7: 31 | M7: 107.5 | N7: 300 | O7: 132 | P7: 2 | Q7: 121 | R7: 168 | S7: 99.5 | T7: 1 | W7: 84.5 | X7: 95 | Y7: 14 | Z7: 81 | AA7: 89 | AB7: 132 | AI7: 物化生 | AJ7: 10 | AL7: 生物选考10.16班 | AO7: 41 | AP7: 48 | AQ7: 37 | AR7: 24 | AS7: 3 | AT7: 6
A8: 缪定衡 | B8: 1315231909 | C8: 32370010238 | D8: 一中 | E8: 物理类 | G8: 19 | H8: 628.5 | I8: 643.5 | J8: 7 | K8: 48 | L8: 33 | M8: 121 | N8: 9 | O8: 123 | P8: 13 | Q8: 131 | R8: 29 | S8: 78.5 | T8: 100 | W8: 86.5 | X8: 96 | Y8: 7 | Z8: 88.5 | AA8: 94 | AB8: 20 | AI8: 物化生 | AJ8: 9 | AO8: 21 | AP8: 132 | AQ8: 12 | AR8: 55 | AS8: 45 | AT8: 7
A9: 许皓 | B9: 1315231920 | C9: 32370010542 | D9: 一中 | E9: 物理类 | G9: 19 | H9: 625 | I9: 642 | J9: 8 | K9: 33 | L9: 36 | M9: 115.5 | N9: 55 | O9: 120 | P9: 26 | Q9: 136.5 | R9: 2 | S9: 84 | T9: 48 | W9: 86.5 | X9: 96 | Y9: 7 | Z9: 82.5 | AA9: 90 | AB9: 99 | AI9: 物化生 | AJ9: 20 | AO9: 11 | AP9: 33 | AQ9: 15 | AR9: 41 | AS9: 22 | AT9: 8
A10: 蔡源培 | B10: 1315231914 | C10: 32370010368 | D10: 一中 | E10: 物理类 | G10: 19 | H10: 619 | I10: 642 | J10: 8 | K10: -3 | L10: 36 | M10: 119.5 | N10: 17 | O10: 125.5 | P10: 7 | Q10: 133 | R10: 12 | S10: 82 | T10: 65 | W10: 73.5 | X10: 90 | Y10: 116 | Z10: 85.5 | AA10: 92 | AB10: 50 | AI10: 物化生 | AJ10: 14 | AO10: 21 | AP10: 3 | AQ10: 10 | AR10: 5 | AS10: 7 | AT10: 8
A11: 陈文杰 | B11: 1315231923 | C11: 32370010571 | D11: 一中 | E11: 物理类 | G11: 19 | H11: 621 | I11: 641.5 | J11: 10 | K11: 19 | L11: 38 | M11: 116 | N11: 51 | O11: 115.5 | P11: 57 | Q11: 129.5 | R11: 46 | S11: 92.5 | T11: 13 | W11: 77 | X11: 92 | Y11: 62 | Z11: 90.5 | AA11: 96 | AB11: 10 | AI11: 物化生 | AJ11: 23 | AO11: 6 | AP11: 44 | AQ11: 21 | AR11: 29 | AS11: 6 | AT11: 10
A12: 郭嘉铭 | B12: 1315231932 | C12: 32370010708 | D12: 一中 | E12: 物理类 | G12: 19 | H12: 627.5 | I12: 641.5 | J12: 10 | K12: -8 | L12: 38 | M12: 108.5 | N12: 258 | O12: 115 | P12: 64 | Q12: 136 | R12: 3 | S12: 89 | T12: 20 | W12: 85 | X12: 95 | Y12: 12 | Z12: 94 | AA12: 98 | AB12: 1 | AI12: 物化生 | AJ12: 32 | AO12: 73 | AP12: 23 | AQ12: 4 | AR12: 2 | AS12: 15 | AT12: 10
A13: 赵晨悦 | B13: 1315231907 | C13: 32370010203 | D13: 一中 | E13: 物理类 | G13: 19 | H13: 625.5 | I13: 641.5 | J13: 10 | K13: -7 | L13: 38 | M13: 113.5 | N13: 101 | O13: 118 | P13: 44 | Q13: 129 | R13: 49 | S13: 93 | T13: 12 | W13: 86 | X13: 95 | Y13: 10 | Z13: 86 | AA13: 93 | AB13: 43 | AI13: 物化生 | AJ13: 7 | AO13: 19 | AP13: 2 | AQ13: 6 | AR13: 3 | AS13: 35 | AT13: 10
A14: 黄熙杰 | B14: 1315231918 | C14: 32370010520 | D14: 一中 | E14: 物理类 | G14: 19 | H14: 621 | I14: 640 | J14: 13 | K14: 8 | L14: 48 | M14: 112 | N14: 138 | O14: 128 | P14: 4 | Q14: 125 | R14: 92 | S14: 88 | T14: 24 | W14: 78 | X14: 92 | Y14: 54 | Z14: 90 | AA14: 95 | AB14: 13 | AI14: 物化生 | AJ14: 18 | AO14: 54 | AP14: 10 | AQ14: 7 | AR14: 21 | AS14: 5 | AT14: 13
A15: 范志华 | B15: 1315230923 | C15: 32370010383 | D15: 一中 | E15: 物理类 | G15: 9 | H15: 622 | I15: 639 | J15: 14 | K15: 30 | L15: 52 | M15: 112 | N15: 138 | O15: 122 | P15: 16 | Q15: 136 | R15: 3 | S15: 81 | T15: 76 | W15: 82.5 | X15: 94 | Y15: 26 | Z15: 88.5 | AA15: 94 | AB15: 20 | AI15: 物化生 | AJ15: 23 | AO15: 36 | AP15: 27 | AQ15: 63 | AR15: 44 | AS15: 31 | AT15: 14
A16: 王晗鉴 | B16: 1315231933 | C16: 32370010748 | D16: 一中 | E16: 物理类 | G16: 19 | H16: 615.5 | I16: 637.5 | J16: 15 | K16: -14 | L16: 58 | M16: 114.5 | N16: 74 | O16: 114 | P16: 69 | Q16: 130.5 | R16: 32 | S16: 94.5 | T16: 6 | W16: 75 | X16: 91 | Y16: 88 | Z16: 87 | AA16: 93 | AB16: 34 | AI16: 物化生 | AJ16: 33 | AO16: 4 | AP16: 15 | AQ16: 3 | AR16: 1 | AS16: 1 | AT16: 15
A17: 郭思辰 | B17: 1315230937 | C17: 32370010568 | D17: 一中 | E17: 物理类 | G17: 9 | H17: 621.5 | I17: 634.5 | J17: 16 | K17: 1 | L17: 70 | M17: 111 | N17: 172 | O17: 117.5 | P17: 46 | Q17: 127 | R17: 68 | S17: 88 | T17: 24 | W17: 92 | X17: 98 | Y17: 2 | Z17: 86 | AA17: 93 | AB17: 43 | AI17: 物化生 | AJ17: 37 | AO17: 2 | AP17: 7 | AQ17: 19 | AR17: 17 | AS17: 56 | AT17: 16
A18: 王毓华 | B18: 1315231929 | C18: 32370010656 | D18: 一中 | E18: 物理类 | G18: 19 | H18: 611.5 | I18: 634 | J18: 17 | K18: 61 | L18: 74 | M18: 116.5 | N18: 40 | O18: 122 | P18: 16 | Q18: 125.5 | R18: 89 | S18: 85 | T18: 42 | W18: 74.5 | X18: 91 | Y18: 102 | Z18: 88 | AA18: 94 | AB18: 28 | AI18: 物化生 | AJ18: 29 | AO18: 32 | AP18: 8 | AQ18: 24 | AR18: 78 | AS18: 2 | AT18: 17
A19: 杨皓程 | B19: 1315231901 | C19: 32370010024 | D19: 一中 | E19: 物理类 | G19: 19 | H19: 620.5 | I19: 633 | J19: 18 | K19: -12 | L19: 79 | M19: 113.5 | N19: 101 | O19: 110.5 | P19: 96 | Q19: 126.5 | R19: 74 | S19: 87.5 | T19: 27 | W19: 89 | X19: 97 | Y19: 5 | Z19: 93.5 | AA19: 98 | AB19: 3 | AI19: 物化生 | AJ19: 1 | AO19: 13 | AP19: 6 | AQ19: 52 | AR19: 6 | AS19: 40 | AT19: 18
... A22: 王梓棋 | B22: 1315231912 | C22: 32370010297 | D22: 一中 | E22: 物理类 | G22: 19 | H22: 605.5 | I22: 629 | J22: 21 | K22: -14 | L22: 96 | M22: 111.5 | N22: 155 | O22: 120 | P22: 26 | Q22: 127.5 | R22: 60 | S22: 87 | T22: 32 | W22: 71 | X22: 89 | Y22: 149 | Z22: 88.5 | AA22: 94 | AB22: 20 | AI22: 物化生 | AJ22: 12 | AO22: 3 | AP22: 13 | AQ22: 11 | AR22: 7 | AS22: 35 | AT22: 21
A23: 张栩芸 | B23: 1315231922 | C23: 32370010509 | D23: 一中 | E23: 物理类 | G23: 19 | H23: 610.5 | I23: 628.5 | J23: 22 | K23: 17 | L23: 98 | M23: 113 | N23: 112 | O23: 123 | P23: 13 | Q23: 111.5 | R23: 371 | S23: 94 | T23: 8 | W23: 84.5 | X23: 95 | Y23: 14 | Z23: 84.5 | AA23: 92 | AB23: 66 | AI23: 物化生 | AJ23: 22 | AL23: 生物选考10.16班 | AO23: 39 | AP23: 33 | AQ23: 22 | AR23: 39 | AS23: 17 | AT23: 22
A24: 郭力文 | B24: 1315231911 | C24: 32370010290 | D24: 一中 | E24: 物理类 | G24: 19 | H24: 617 | I24: 627 | J24: 23 | K24: 8 | L24: 104 | M24: 113.5 | N24: 101 | O24: 119 | P24: 36 | Q24: 129.5 | R24: 46 | S24: 70 | T24: 226 | W24: 91 | X24: 97 | Y24: 4 | Z24: 94 | AA24: 98 | AB24: 1 | AI24: 物化生 | AJ24: 11 | AO24: 8 | AP24: 21 | AQ24: 30 | AR24: 31 | AS24: 11 | AT24: 23
A25: 黄陈栩 | B25: 1315231015 | C25: 32370010268 | D25: 一中 | E25: 物理类 | G25: 10 | H25: 592.75 | I25: 627 | J25: 23 | K25: 28 | L25: 104 | M25: 116.5 | N25: 40 | O25: 105.5 | P25: 170 | Q25: 133 | R25: 12 | S25: 87 | T25: 32 | W25: 77 | X25: 92 | Y25: 62 | AC25: 73.75 | AD25: 93 | AE25: 12 | AI25: 物化政 | AJ25: 15 | AO25: 10 | AP25: 35 | AQ25: 49 | AR25: 51 | AS25: 51 | AT25: 23
A26: 李彦德 | B26: 1315230921 | C26: 32370010267 | D26: 一中 | E26: 物理类 | G26: 9 | H26: 605 | I26: 626 | J26: 25 | K26: 78 | L26: 111 | M26: 116.5 | N26: 40 | O26: 116 | P26: 54 | Q26: 120.5 | R26: 180 | S26: 87 | T26: 32 | W26: 75 | X26: 91 | Y26: 88 | Z26: 90 | AA26: 95 | AB26: 13 | AI26: 物化生 | AJ26: 21 | AO26: 43 | AP26: 12 | AQ26: 39 | AR26: 103 | AS26: 43 | AT26: 25
A27: 谢莹莹 | B27: 1315231906 | C27: 32370010152 | D27: 一中 | E27: 物理类 | G27: 19 | H27: 602.5 | I27: 625.5 | J27: 26 | K27: 34 | L27: 116 | M27: 119 | N27: 21 | O27: 120.5 | P27: 23 | Q27: 133.5 | R27: 9 | S27: 69.5 | T27: 241 | W27: 74.5 | X27: 91 | Y27: 102 | Z27: 85.5 | AA27: 92 | AB27: 50 | AI27: 物化生 | AJ27: 6 | AO27: 68 | AP27: 26 | AQ27: 51 | AR27: 60 | AS27: 89 | AT27: 26
A28: 李想 | B28: 1315231913 | C28: 32370010331 | D28: 一中 | E28: 物理类 | G28: 19 | H28: 604 | I28: 624.5 | J28: 27 | K28: -5 | L28: 121 | M28: 113.5 | N28: 101 | O28: 110.5 | P28: 96 | Q28: 129 | R28: 49 | S28: 83.5 | T28: 50 | W28: 76.5 | X28: 92 | Y28: 66 | Z28: 91 | AA28: 96 | AB28: 9 | AI28: 物化生 | AJ28: 13 | AO28: 76 | AP28: 31 | AQ28: 25 | AR28: 22 | AS28: 30 | AT28: 27
A29: 郑楷杰 | B29: 1315231046 | C29: 32370010707 | D29: 一中 | E29: 物理类 | G29: 10 | H29: 599.5 | I29: 624.5 | J29: 27 | K29: 51 | L29: 121 | M29: 123 | N29: 3 | O29: 94 | P29: 381 | Q29: 131 | R29: 29 | S29: 84.5 | T29: 45 | W29: 84 | X29: 95 | Y29: 17 | AF29: 83 | AG29: 97 | AH29: 1 | AI29: 物化地 | AJ29: 46 | AN29: 地理选考10.16班 | AO29: 5 | AP29: 110 | AQ29: 674 | AR29: 78 | AS29: 27 | AT29: 27
A30: 杨镇宏 | B30: 1315231903 | C30: 32370010086 | D30: 一中 | E30: 物理类 | G30: 19 | H30: 602 | I30: 624 | J30: 29 | K30: -13 | L30: 127 | M30: 119 | N30: 21 | O30: 111 | P30: 91 | Q30: 130.5 | R30: 32 | S30: 80.5 | T30: 81 | W30: 79.5 | X30: 93 | Y30: 43 | Z30: 81.5 | AA30: 90 | AB30: 122 | AI30: 物化生 | AJ30: 3 | AO30: 26 | AP30: 25 | AQ30: 9 | AR30: 16 | AS30: 17 | AT30: 29
A31: 苏陈烨 | B31: 1315230925 | C31: 32370010475 | D31: 一中 | E31: 物理类 | G31: 9 | H31: 604 | I31: 623.5 | J31: 30 | K31: -12 | L31: 129 | M31: 109.5 | N31: 226 | O31: 113.5 | P31: 77 | Q31: 119.5 | R31: 200 | S31: 96 | T31: 3 | W31: 81 | X31: 93 | Y31: 35 | Z31: 84.5 | AA31: 92 | AB31: 66 | AI31: 物化生 | AJ31: 25 | AO31: 47 | AP31: 14 | AQ31: 17 | AR31: 18 | AS31: 16 | AT31: 30
A32: 李思翰 | B32: 7035231052 | C32: 32570010486 | D32: 7001扆山 | E32: 物理类 | F32: 扆山 | G32: 10 | H32: 601 | I32: 621 | J32: 31 | K32: -21 | L32: 138 | M32: 103 | N32: 487 | O32: 127 | P32: 4 | Q32: 112 | R32: 360 | S32: 96 | T32: 3 | W32: 82 | X32: 94 | Y32: 29 | Z32: 81 | AA32: 89 | AB32: 132 | AJ32: 60 | AP32: 147 | AQ32: 59 | AR32: 10 | AT32: 31
A33: 林勇廷 | B33: 1315231926 | C33: 32370010599 | D33: 一中 | E33: 物理类 | G33: 19 | H33: 593 | I33: 621.5 | J33: 31 | K33: 1 | L33: 138 | M33: 107.5 | N33: 300 | O33: 128 | P33: 4 | Q33: 124.5 | R33: 100 | S33: 87.5 | T33: 27 | W33: 68.5 | X33: 88 | Y33: 182 | Z33: 77 | AA33: 86 | AB33: 212 | AI33: 物化生 | AJ33: 26 | AO33: 16 | AP33: 22 | AQ33: 13 | AR33: 32 | AS33: 10 | AT33: 31
A34: 彭俊鑫 | B34: 1315230913 | C34: 32370010179 | D34: 一中 | E34: 物理类 | G34: 9 | H34: 602.5 | I34: 620.5 | J34: 32 | K34: -22 | L34: 145 | M34: 108 | N34: 278 | O34: 119.5 | P34: 33 | Q34: 130.5 | R34: 32 | S34: 75.5 | T34: 151 | W34: 84.5 | X34: 95 | Y34: 14 | Z34: 84.5 | AA34: 92 | AB34: 66 | AI34: 物化生 | AJ34: 13 | AO34: 105 | AP34: 17 | AQ34: 41 | AR34: 10 | AS34: 23 | AT34: 32
A35: 叶紫 | B35: 1315230904 | C35: 32370010030 | D35: 一中 | E35: 物理类 | G35: 9 | H35: 599.75 | I35: 620.5 | J35: 32 | K35: 58 | L35: 145 | M35: 114.5 | N35: 74 | O35: 107.5 | P35: 129 | Q35: 133.5 | R35: 9 | S35: 78 | T35: 109 | W35: 76.5 | X35: 92 | Y35: 66 | Z35: 89.75 | AA35: 95 | AB35: 15 | AI35: 物化生 | AJ35: 4 | AO35: 30 | AP35: 77 | AQ35: 98 | AR35: 90 | AS35: 27 | AT35: 32
A36: 陈思尹 | B36: 1315230901 | C36: 32370010004 | D36: 一中 | E36: 物理类 | G36: 9 | H36: 598 | I36: 620 | J36: 34 | K36: 26 | L36: 148 | M36: 114 | N36: 84 | O36: 120.5 | P36: 23 | Q36: 119 | R36: 212 | S36: 81.5 | T36: 71 | W36: 75.5 | X36: 91 | Y36: 79 | Z36: 87.5 | AA36: 94 | AB36: 32 | AI36: 物化生 | AJ36: 1 | AO36: 24 | AP36: 43 | AQ36: 67 | AR36: 60 | AS36: 63 | AT36: 34
A37: 兰天泽 | B37: 1315231917 | C37: 32370010493 | D37: 一中 | E37: 物理类 | G37: 19 | H37: 605 | I37: 619.5 | J37: 35 | K37: -24 | L37: 154 | M37: 109 | N37: 245 | O37: 107.5 | P37: 129 | Q37: 133.5 | R37: 9 | S37: 77.5 | T37: 116 | W37: 87 | X37: 96 | Y37: 6 | Z37: 90.5 | AA37: 96 | AB37: 10 | AI37: 物化生 | AJ37: 17 | AO37: 7 | AP37: 11 | AQ37: 5 | AR37: 11 | AS37: 8 | AT37: 35
A38: 杨竣淇 | B38: 1315230941 | C38: 32370010732 | D38: 一中 | E38: 物理类 | G38: 9 | H38: 595.5 | I38: 619 | J38: 36 | K38: -4 | L38: 160 | M38: 115.5 | N38: 55 | O38: 115 | P38: 64 | Q38: 115.5 | R38: 288 | S38: 90 | T38: 19 | W38: 74.5 | X38: 91 | Y38: 102 | Z38: 85 | AA38: 92 | AB38: 57 | AI38: 物化生 | AJ38: 41 | AO38: 185 | AP38: 70 | AQ38: 142 | AR38: 32 | AS38: 128 | AT38: 36
A39: 叶矞坤 | B39: 1315230905 | C39: 32370010172 | D39: 一中 | E39: 物理类 | G39: 9 | H39: 594.5 | I39: 618.5 | J39: 37 | K39: 126 | L39: 166 | M39: 117 | N39: 39 | O39: 120.5 | P39: 23 | Q39: 130.5 | R39: 32 | S39: 67.5 | T39: 275 | W39: 70.5 | X39: 89 | Y39: 152 | Z39: 88.5 | AA39: 94 | AB39: 20 | AI39: 物化生 | AJ39: 5 | AO39: 86 | AP39: 177 | AQ39: 95 | AR39: 163 | AS39: 79 | AT39: 37
A40: 占嘉恒 | B40: 1315231905 | C40: 32370010149 | D40: 一中 | E40: 物理类 | G40: 19 | H40: 594.5 | I40: 618.5 | J40: 37 | K40: 11 | L40: 166 | M40: 110 | N40: 209 | O40: 118.5 | P40: 38 | Q40: 126.5 | R40: 74 | S40: 84.5 | T40: 45 | W40: 75 | X40: 91 | Y40: 88 | Z40: 80 | AA40: 88 | AB40: 152 | AI40: 物化生 | AJ40: 5 | AO40: 111 | AP40: 60 | AQ40: 8 | AR40: 48 | AS40: 37 | AT40: 37
A41: 缪良松 | B41: 1315230916 | C41: 32370010271 | D41: 一中 | E41: 物理类 | G41: 9 | H41: 593.5 | I41: 617.5 | J41: 39 | K41: 77 | L41: 171 | M41: 109.5 | N41: 226 | O41: 122.5 | P41: 15 | Q41: 122 | R41: 142 | S41: 80.5 | T41: 81 | W41: 74.5 | X41: 91 | Y41: 102 | Z41: 84.5 | AA41: 92 | AB41: 66 | AI41: 物化生 | AJ41: 16 | AO41: 125 | AP41: 53 | AQ41: 80 | AR41: 116 | AS41: 20 | AT41: 39
A42: 林文华 | B42: 1315230938 | C42: 32370010677 | D42: 一中 | E42: 物理类 | G42: 9 | H42: 605 | I42: 617 | J42: 40 | K42: -27 | L42: 177 | M42: 104 | N42: 450 | O42: 117.5 | P42: 46 | Q42: 121 | R42: 168 | S42: 82.5 | T42: 60 | W42: 94 | X42: 99 | Y42: 1 | Z42: 86 | AA42: 93 | AB42: 43 | AI42: 物化生 | AJ42: 38 | AO42: 38 | AP42: 39 | AQ42: 31 | AR42: 13 | AS42: 74 | AT42: 40
...

Sheet 总分(一中)
A1: 姓名 | B1: 考号 | C1: 学号 | D1: 学籍校 | E1: 科类 | F1: 备注 | G1: 班级 | H1: 总分 | I1: 赋分总分 | J1: 赋分总分排名 | K1: 进退步 | L1: 联考排名 | M1: 语文 | N1: 语文排名 | O1: 数学 | P1: 数学排名 | Q1: 英语 | R1: 英语排名 | S1: 物理 | T1: 物理排名 | U1: 历史 | V1: 历史排名 | W1: 化学 | X1: 化学赋分 | Y1: 化学排名 | Z1: 生物 | AA1: 生物赋分 | AB1: 生物排名 | AC1: 政治 | AD1: 政治赋分 | AE1: 政治排名 | AF1: 地理 | AG1: 地理赋分 | AH1: 地理排名 | AI1: 选科 | AJ1: 座号 | AK1: 化学教学班名称 | AL1: 生物教学班名称 | AM1: 政治教学班名称 | AN1: 地理教学班名称 | AO1: 上月考1排名 | AP1: 上月考2排名 | AQ1: 上月考4排名 | AR1: 上月考5排名 | AS1: 上半期考排名 | AT1: 上期末考排名
A2: 钟亿杨 | B2: 1315231925 | C2: 32370010581 | D2: 一中 | E2: 物理类 | G2: 19 | H2: 646 | I2: 669.5 | J2: 1 | K2: 3 | L2: 2 | M2: 115 | N2: 66 | O2: 131.5 | P2: 3 | Q2: 136 | R2: 3 | S2: 99 | T2: 2 | W2: 71.5 | X2: 90 | Y2: 144 | Z2: 93 | AA2: 98 | AB2: 4 | AI2: 物化生 | AJ2: 25 | AO2: 1 | AP2: 3 | AQ2: 1 | AR2: 4 | AS2: 11 | AT2: 1
A3: 吴凯杰 | B3: 1315231916 | C3: 32370010490 | D3: 一中 | E3: 物理类 | G3: 19 | H3: 631 | I3: 649 | J3: 2 | K3: 11 | L3: 23 | M3: 118.5 | N3: 28 | O3: 117.5 | P3: 46 | Q3: 132.5 | R3: 21 | S3: 94.5 | T3: 6 | W3: 83.5 | X3: 94 | Y3: 21 | Z3: 84.5 | AA3: 92 | AB3: 66 | AI3: 物化生 | AJ3: 16 | AO3: 15 | AP3: 1 | AQ3: 2 | AR3: 13 | AS3: 4 | AT3: 2
